[2023-07-29T22:35:00.497+0300] {processor.py:156} INFO - Started process (PID=26) to work on /opt/airflow/dags/google_trends_dag.py
[2023-07-29T22:35:00.498+0300] {processor.py:799} INFO - Processing file /opt/airflow/dags/google_trends_dag.py for tasks to queue
[2023-07-29T22:35:00.499+0300] {logging_mixin.py:149} INFO - [2023-07-29T22:35:00.499+0300] {dagbag.py:541} INFO - Filling up the DagBag from /opt/airflow/dags/google_trends_dag.py
[2023-07-29T22:35:00.522+0300] {logging_mixin.py:149} INFO - [2023-07-29T22:35:00.517+0300] {dagbag.py:350} ERROR - Failed to import: /opt/airflow/dags/google_trends_dag.py
Traceback (most recent call last):
  File "/home/airflow/.local/lib/python3.9/site-packages/airflow/models/dagbag.py", line 346, in parse
    loader.exec_module(new_module)
  File "<frozen importlib._bootstrap_external>", line 850, in exec_module
  File "<frozen importlib._bootstrap>", line 228, in _call_with_frames_removed
  File "/opt/airflow/dags/google_trends_dag.py", line 74, in <module>
    dag_creator = GooogleTrendsMonthly()
  File "/opt/airflow/dags/google_trends_dag.py", line 41, in __init__
    self.dag:DAG = self.create_dag()
  File "/opt/airflow/dags/google_trends_dag.py", line 54, in create_dag
    update_monthly: PythonOperator = PythonOperator(
  File "/home/airflow/.local/lib/python3.9/site-packages/airflow/models/baseoperator.py", line 429, in apply_defaults
    result = func(self, **kwargs, default_args=default_args)
  File "/home/airflow/.local/lib/python3.9/site-packages/airflow/operators/python.py", line 168, in __init__
    raise AirflowException("`python_callable` param must be callable")
airflow.exceptions.AirflowException: `python_callable` param must be callable
[2023-07-29T22:35:00.523+0300] {processor.py:811} WARNING - No viable dags retrieved from /opt/airflow/dags/google_trends_dag.py
[2023-07-29T22:35:00.561+0300] {processor.py:178} INFO - Processing /opt/airflow/dags/google_trends_dag.py took 0.067 seconds
[2023-07-29T22:35:30.746+0300] {processor.py:156} INFO - Started process (PID=35) to work on /opt/airflow/dags/google_trends_dag.py
[2023-07-29T22:35:30.747+0300] {processor.py:799} INFO - Processing file /opt/airflow/dags/google_trends_dag.py for tasks to queue
[2023-07-29T22:35:30.748+0300] {logging_mixin.py:149} INFO - [2023-07-29T22:35:30.748+0300] {dagbag.py:541} INFO - Filling up the DagBag from /opt/airflow/dags/google_trends_dag.py
[2023-07-29T22:35:30.774+0300] {logging_mixin.py:149} INFO - [2023-07-29T22:35:30.771+0300] {dagbag.py:350} ERROR - Failed to import: /opt/airflow/dags/google_trends_dag.py
Traceback (most recent call last):
  File "/home/airflow/.local/lib/python3.9/site-packages/airflow/models/dagbag.py", line 346, in parse
    loader.exec_module(new_module)
  File "<frozen importlib._bootstrap_external>", line 850, in exec_module
  File "<frozen importlib._bootstrap>", line 228, in _call_with_frames_removed
  File "/opt/airflow/dags/google_trends_dag.py", line 74, in <module>
    dag_creator = GooogleTrendsMonthly()
  File "/opt/airflow/dags/google_trends_dag.py", line 41, in __init__
    self.dag:DAG = self.create_dag()
  File "/opt/airflow/dags/google_trends_dag.py", line 54, in create_dag
    update_monthly: PythonOperator = PythonOperator(
  File "/home/airflow/.local/lib/python3.9/site-packages/airflow/models/baseoperator.py", line 429, in apply_defaults
    result = func(self, **kwargs, default_args=default_args)
  File "/home/airflow/.local/lib/python3.9/site-packages/airflow/operators/python.py", line 168, in __init__
    raise AirflowException("`python_callable` param must be callable")
airflow.exceptions.AirflowException: `python_callable` param must be callable
[2023-07-29T22:35:30.775+0300] {processor.py:811} WARNING - No viable dags retrieved from /opt/airflow/dags/google_trends_dag.py
[2023-07-29T22:35:30.809+0300] {processor.py:178} INFO - Processing /opt/airflow/dags/google_trends_dag.py took 0.070 seconds
[2023-07-29T22:36:00.906+0300] {processor.py:156} INFO - Started process (PID=43) to work on /opt/airflow/dags/google_trends_dag.py
[2023-07-29T22:36:00.908+0300] {processor.py:799} INFO - Processing file /opt/airflow/dags/google_trends_dag.py for tasks to queue
[2023-07-29T22:36:00.908+0300] {logging_mixin.py:149} INFO - [2023-07-29T22:36:00.908+0300] {dagbag.py:541} INFO - Filling up the DagBag from /opt/airflow/dags/google_trends_dag.py
[2023-07-29T22:36:00.924+0300] {logging_mixin.py:149} INFO - [2023-07-29T22:36:00.922+0300] {dagbag.py:350} ERROR - Failed to import: /opt/airflow/dags/google_trends_dag.py
Traceback (most recent call last):
  File "/home/airflow/.local/lib/python3.9/site-packages/airflow/models/dagbag.py", line 346, in parse
    loader.exec_module(new_module)
  File "<frozen importlib._bootstrap_external>", line 850, in exec_module
  File "<frozen importlib._bootstrap>", line 228, in _call_with_frames_removed
  File "/opt/airflow/dags/google_trends_dag.py", line 74, in <module>
    dag_creator = GooogleTrendsMonthly()
  File "/opt/airflow/dags/google_trends_dag.py", line 41, in __init__
    self.dag:DAG = self.create_dag()
  File "/opt/airflow/dags/google_trends_dag.py", line 54, in create_dag
    update_monthly: PythonOperator = PythonOperator(
  File "/home/airflow/.local/lib/python3.9/site-packages/airflow/models/baseoperator.py", line 429, in apply_defaults
    result = func(self, **kwargs, default_args=default_args)
  File "/home/airflow/.local/lib/python3.9/site-packages/airflow/operators/python.py", line 168, in __init__
    raise AirflowException("`python_callable` param must be callable")
airflow.exceptions.AirflowException: `python_callable` param must be callable
[2023-07-29T22:36:00.925+0300] {processor.py:811} WARNING - No viable dags retrieved from /opt/airflow/dags/google_trends_dag.py
[2023-07-29T22:36:00.983+0300] {processor.py:178} INFO - Processing /opt/airflow/dags/google_trends_dag.py took 0.081 seconds
[2023-07-29T22:36:31.126+0300] {processor.py:156} INFO - Started process (PID=51) to work on /opt/airflow/dags/google_trends_dag.py
[2023-07-29T22:36:31.127+0300] {processor.py:799} INFO - Processing file /opt/airflow/dags/google_trends_dag.py for tasks to queue
[2023-07-29T22:36:31.128+0300] {logging_mixin.py:149} INFO - [2023-07-29T22:36:31.128+0300] {dagbag.py:541} INFO - Filling up the DagBag from /opt/airflow/dags/google_trends_dag.py
[2023-07-29T22:36:31.149+0300] {logging_mixin.py:149} INFO - [2023-07-29T22:36:31.147+0300] {dagbag.py:350} ERROR - Failed to import: /opt/airflow/dags/google_trends_dag.py
Traceback (most recent call last):
  File "/home/airflow/.local/lib/python3.9/site-packages/airflow/models/dagbag.py", line 346, in parse
    loader.exec_module(new_module)
  File "<frozen importlib._bootstrap_external>", line 850, in exec_module
  File "<frozen importlib._bootstrap>", line 228, in _call_with_frames_removed
  File "/opt/airflow/dags/google_trends_dag.py", line 74, in <module>
    dag_creator = GooogleTrendsMonthly()
  File "/opt/airflow/dags/google_trends_dag.py", line 41, in __init__
    self.dag:DAG = self.create_dag()
  File "/opt/airflow/dags/google_trends_dag.py", line 54, in create_dag
    update_monthly: PythonOperator = PythonOperator(
  File "/home/airflow/.local/lib/python3.9/site-packages/airflow/models/baseoperator.py", line 429, in apply_defaults
    result = func(self, **kwargs, default_args=default_args)
  File "/home/airflow/.local/lib/python3.9/site-packages/airflow/operators/python.py", line 168, in __init__
    raise AirflowException("`python_callable` param must be callable")
airflow.exceptions.AirflowException: `python_callable` param must be callable
[2023-07-29T22:36:31.150+0300] {processor.py:811} WARNING - No viable dags retrieved from /opt/airflow/dags/google_trends_dag.py
[2023-07-29T22:36:31.182+0300] {processor.py:178} INFO - Processing /opt/airflow/dags/google_trends_dag.py took 0.060 seconds
[2023-07-29T22:37:01.302+0300] {processor.py:156} INFO - Started process (PID=59) to work on /opt/airflow/dags/google_trends_dag.py
[2023-07-29T22:37:01.303+0300] {processor.py:799} INFO - Processing file /opt/airflow/dags/google_trends_dag.py for tasks to queue
[2023-07-29T22:37:01.304+0300] {logging_mixin.py:149} INFO - [2023-07-29T22:37:01.303+0300] {dagbag.py:541} INFO - Filling up the DagBag from /opt/airflow/dags/google_trends_dag.py
[2023-07-29T22:37:01.320+0300] {logging_mixin.py:149} INFO - [2023-07-29T22:37:01.319+0300] {dagbag.py:350} ERROR - Failed to import: /opt/airflow/dags/google_trends_dag.py
Traceback (most recent call last):
  File "/home/airflow/.local/lib/python3.9/site-packages/airflow/models/dagbag.py", line 346, in parse
    loader.exec_module(new_module)
  File "<frozen importlib._bootstrap_external>", line 850, in exec_module
  File "<frozen importlib._bootstrap>", line 228, in _call_with_frames_removed
  File "/opt/airflow/dags/google_trends_dag.py", line 74, in <module>
    dag_creator = GooogleTrendsMonthly()
  File "/opt/airflow/dags/google_trends_dag.py", line 41, in __init__
    self.dag:DAG = self.create_dag()
  File "/opt/airflow/dags/google_trends_dag.py", line 54, in create_dag
    update_monthly: PythonOperator = PythonOperator(
  File "/home/airflow/.local/lib/python3.9/site-packages/airflow/models/baseoperator.py", line 429, in apply_defaults
    result = func(self, **kwargs, default_args=default_args)
  File "/home/airflow/.local/lib/python3.9/site-packages/airflow/operators/python.py", line 168, in __init__
    raise AirflowException("`python_callable` param must be callable")
airflow.exceptions.AirflowException: `python_callable` param must be callable
[2023-07-29T22:37:01.323+0300] {processor.py:811} WARNING - No viable dags retrieved from /opt/airflow/dags/google_trends_dag.py
[2023-07-29T22:37:01.351+0300] {processor.py:178} INFO - Processing /opt/airflow/dags/google_trends_dag.py took 0.053 seconds
[2023-07-29T22:37:31.476+0300] {processor.py:156} INFO - Started process (PID=67) to work on /opt/airflow/dags/google_trends_dag.py
[2023-07-29T22:37:31.476+0300] {processor.py:799} INFO - Processing file /opt/airflow/dags/google_trends_dag.py for tasks to queue
[2023-07-29T22:37:31.477+0300] {logging_mixin.py:149} INFO - [2023-07-29T22:37:31.477+0300] {dagbag.py:541} INFO - Filling up the DagBag from /opt/airflow/dags/google_trends_dag.py
[2023-07-29T22:37:31.499+0300] {logging_mixin.py:149} INFO - [2023-07-29T22:37:31.496+0300] {dagbag.py:350} ERROR - Failed to import: /opt/airflow/dags/google_trends_dag.py
Traceback (most recent call last):
  File "/home/airflow/.local/lib/python3.9/site-packages/airflow/models/dagbag.py", line 346, in parse
    loader.exec_module(new_module)
  File "<frozen importlib._bootstrap_external>", line 850, in exec_module
  File "<frozen importlib._bootstrap>", line 228, in _call_with_frames_removed
  File "/opt/airflow/dags/google_trends_dag.py", line 74, in <module>
    dag_creator = GooogleTrendsMonthly()
  File "/opt/airflow/dags/google_trends_dag.py", line 41, in __init__
    self.dag:DAG = self.create_dag()
  File "/opt/airflow/dags/google_trends_dag.py", line 54, in create_dag
    update_monthly: PythonOperator = PythonOperator(
  File "/home/airflow/.local/lib/python3.9/site-packages/airflow/models/baseoperator.py", line 429, in apply_defaults
    result = func(self, **kwargs, default_args=default_args)
  File "/home/airflow/.local/lib/python3.9/site-packages/airflow/operators/python.py", line 168, in __init__
    raise AirflowException("`python_callable` param must be callable")
airflow.exceptions.AirflowException: `python_callable` param must be callable
[2023-07-29T22:37:31.499+0300] {processor.py:811} WARNING - No viable dags retrieved from /opt/airflow/dags/google_trends_dag.py
[2023-07-29T22:37:31.526+0300] {processor.py:178} INFO - Processing /opt/airflow/dags/google_trends_dag.py took 0.054 seconds
[2023-07-29T22:38:01.643+0300] {processor.py:156} INFO - Started process (PID=75) to work on /opt/airflow/dags/google_trends_dag.py
[2023-07-29T22:38:01.645+0300] {processor.py:799} INFO - Processing file /opt/airflow/dags/google_trends_dag.py for tasks to queue
[2023-07-29T22:38:01.646+0300] {logging_mixin.py:149} INFO - [2023-07-29T22:38:01.645+0300] {dagbag.py:541} INFO - Filling up the DagBag from /opt/airflow/dags/google_trends_dag.py
[2023-07-29T22:38:01.672+0300] {logging_mixin.py:149} INFO - [2023-07-29T22:38:01.669+0300] {dagbag.py:350} ERROR - Failed to import: /opt/airflow/dags/google_trends_dag.py
Traceback (most recent call last):
  File "/home/airflow/.local/lib/python3.9/site-packages/airflow/models/dagbag.py", line 346, in parse
    loader.exec_module(new_module)
  File "<frozen importlib._bootstrap_external>", line 850, in exec_module
  File "<frozen importlib._bootstrap>", line 228, in _call_with_frames_removed
  File "/opt/airflow/dags/google_trends_dag.py", line 74, in <module>
    dag_creator = GooogleTrendsMonthly()
  File "/opt/airflow/dags/google_trends_dag.py", line 41, in __init__
    self.dag:DAG = self.create_dag()
  File "/opt/airflow/dags/google_trends_dag.py", line 54, in create_dag
    update_monthly: PythonOperator = PythonOperator(
  File "/home/airflow/.local/lib/python3.9/site-packages/airflow/models/baseoperator.py", line 429, in apply_defaults
    result = func(self, **kwargs, default_args=default_args)
  File "/home/airflow/.local/lib/python3.9/site-packages/airflow/operators/python.py", line 168, in __init__
    raise AirflowException("`python_callable` param must be callable")
airflow.exceptions.AirflowException: `python_callable` param must be callable
[2023-07-29T22:38:01.673+0300] {processor.py:811} WARNING - No viable dags retrieved from /opt/airflow/dags/google_trends_dag.py
[2023-07-29T22:38:01.708+0300] {processor.py:178} INFO - Processing /opt/airflow/dags/google_trends_dag.py took 0.070 seconds
[2023-07-29T22:38:31.837+0300] {processor.py:156} INFO - Started process (PID=83) to work on /opt/airflow/dags/google_trends_dag.py
[2023-07-29T22:38:31.838+0300] {processor.py:799} INFO - Processing file /opt/airflow/dags/google_trends_dag.py for tasks to queue
[2023-07-29T22:38:31.838+0300] {logging_mixin.py:149} INFO - [2023-07-29T22:38:31.838+0300] {dagbag.py:541} INFO - Filling up the DagBag from /opt/airflow/dags/google_trends_dag.py
[2023-07-29T22:38:31.856+0300] {logging_mixin.py:149} INFO - [2023-07-29T22:38:31.854+0300] {dagbag.py:350} ERROR - Failed to import: /opt/airflow/dags/google_trends_dag.py
Traceback (most recent call last):
  File "/home/airflow/.local/lib/python3.9/site-packages/airflow/models/dagbag.py", line 346, in parse
    loader.exec_module(new_module)
  File "<frozen importlib._bootstrap_external>", line 850, in exec_module
  File "<frozen importlib._bootstrap>", line 228, in _call_with_frames_removed
  File "/opt/airflow/dags/google_trends_dag.py", line 74, in <module>
    dag_creator = GooogleTrendsMonthly()
  File "/opt/airflow/dags/google_trends_dag.py", line 41, in __init__
    self.dag:DAG = self.create_dag()
  File "/opt/airflow/dags/google_trends_dag.py", line 54, in create_dag
    update_monthly: PythonOperator = PythonOperator(
  File "/home/airflow/.local/lib/python3.9/site-packages/airflow/models/baseoperator.py", line 429, in apply_defaults
    result = func(self, **kwargs, default_args=default_args)
  File "/home/airflow/.local/lib/python3.9/site-packages/airflow/operators/python.py", line 168, in __init__
    raise AirflowException("`python_callable` param must be callable")
airflow.exceptions.AirflowException: `python_callable` param must be callable
[2023-07-29T22:38:31.856+0300] {processor.py:811} WARNING - No viable dags retrieved from /opt/airflow/dags/google_trends_dag.py
[2023-07-29T22:38:31.891+0300] {processor.py:178} INFO - Processing /opt/airflow/dags/google_trends_dag.py took 0.059 seconds
[2023-07-29T22:39:02.043+0300] {processor.py:156} INFO - Started process (PID=91) to work on /opt/airflow/dags/google_trends_dag.py
[2023-07-29T22:39:02.044+0300] {processor.py:799} INFO - Processing file /opt/airflow/dags/google_trends_dag.py for tasks to queue
[2023-07-29T22:39:02.045+0300] {logging_mixin.py:149} INFO - [2023-07-29T22:39:02.045+0300] {dagbag.py:541} INFO - Filling up the DagBag from /opt/airflow/dags/google_trends_dag.py
[2023-07-29T22:39:02.070+0300] {logging_mixin.py:149} INFO - [2023-07-29T22:39:02.068+0300] {dagbag.py:350} ERROR - Failed to import: /opt/airflow/dags/google_trends_dag.py
Traceback (most recent call last):
  File "/home/airflow/.local/lib/python3.9/site-packages/airflow/models/dagbag.py", line 346, in parse
    loader.exec_module(new_module)
  File "<frozen importlib._bootstrap_external>", line 850, in exec_module
  File "<frozen importlib._bootstrap>", line 228, in _call_with_frames_removed
  File "/opt/airflow/dags/google_trends_dag.py", line 74, in <module>
    dag_creator = GooogleTrendsMonthly()
  File "/opt/airflow/dags/google_trends_dag.py", line 41, in __init__
    self.dag:DAG = self.create_dag()
  File "/opt/airflow/dags/google_trends_dag.py", line 54, in create_dag
    update_monthly: PythonOperator = PythonOperator(
  File "/home/airflow/.local/lib/python3.9/site-packages/airflow/models/baseoperator.py", line 429, in apply_defaults
    result = func(self, **kwargs, default_args=default_args)
  File "/home/airflow/.local/lib/python3.9/site-packages/airflow/operators/python.py", line 168, in __init__
    raise AirflowException("`python_callable` param must be callable")
airflow.exceptions.AirflowException: `python_callable` param must be callable
[2023-07-29T22:39:02.071+0300] {processor.py:811} WARNING - No viable dags retrieved from /opt/airflow/dags/google_trends_dag.py
[2023-07-29T22:39:02.097+0300] {processor.py:178} INFO - Processing /opt/airflow/dags/google_trends_dag.py took 0.059 seconds
[2023-07-29T22:39:32.224+0300] {processor.py:156} INFO - Started process (PID=99) to work on /opt/airflow/dags/google_trends_dag.py
[2023-07-29T22:39:32.225+0300] {processor.py:799} INFO - Processing file /opt/airflow/dags/google_trends_dag.py for tasks to queue
[2023-07-29T22:39:32.226+0300] {logging_mixin.py:149} INFO - [2023-07-29T22:39:32.225+0300] {dagbag.py:541} INFO - Filling up the DagBag from /opt/airflow/dags/google_trends_dag.py
[2023-07-29T22:39:32.244+0300] {logging_mixin.py:149} INFO - [2023-07-29T22:39:32.242+0300] {dagbag.py:350} ERROR - Failed to import: /opt/airflow/dags/google_trends_dag.py
Traceback (most recent call last):
  File "/home/airflow/.local/lib/python3.9/site-packages/airflow/models/dagbag.py", line 346, in parse
    loader.exec_module(new_module)
  File "<frozen importlib._bootstrap_external>", line 850, in exec_module
  File "<frozen importlib._bootstrap>", line 228, in _call_with_frames_removed
  File "/opt/airflow/dags/google_trends_dag.py", line 74, in <module>
    dag_creator = GooogleTrendsMonthly()
  File "/opt/airflow/dags/google_trends_dag.py", line 41, in __init__
    self.dag:DAG = self.create_dag()
  File "/opt/airflow/dags/google_trends_dag.py", line 54, in create_dag
    update_monthly: PythonOperator = PythonOperator(
  File "/home/airflow/.local/lib/python3.9/site-packages/airflow/models/baseoperator.py", line 429, in apply_defaults
    result = func(self, **kwargs, default_args=default_args)
  File "/home/airflow/.local/lib/python3.9/site-packages/airflow/operators/python.py", line 168, in __init__
    raise AirflowException("`python_callable` param must be callable")
airflow.exceptions.AirflowException: `python_callable` param must be callable
[2023-07-29T22:39:32.245+0300] {processor.py:811} WARNING - No viable dags retrieved from /opt/airflow/dags/google_trends_dag.py
[2023-07-29T22:39:32.273+0300] {processor.py:178} INFO - Processing /opt/airflow/dags/google_trends_dag.py took 0.053 seconds
[2023-07-29T22:40:02.415+0300] {processor.py:156} INFO - Started process (PID=107) to work on /opt/airflow/dags/google_trends_dag.py
[2023-07-29T22:40:02.417+0300] {processor.py:799} INFO - Processing file /opt/airflow/dags/google_trends_dag.py for tasks to queue
[2023-07-29T22:40:02.417+0300] {logging_mixin.py:149} INFO - [2023-07-29T22:40:02.417+0300] {dagbag.py:541} INFO - Filling up the DagBag from /opt/airflow/dags/google_trends_dag.py
[2023-07-29T22:40:02.440+0300] {logging_mixin.py:149} INFO - [2023-07-29T22:40:02.435+0300] {dagbag.py:350} ERROR - Failed to import: /opt/airflow/dags/google_trends_dag.py
Traceback (most recent call last):
  File "/home/airflow/.local/lib/python3.9/site-packages/airflow/models/dagbag.py", line 346, in parse
    loader.exec_module(new_module)
  File "<frozen importlib._bootstrap_external>", line 850, in exec_module
  File "<frozen importlib._bootstrap>", line 228, in _call_with_frames_removed
  File "/opt/airflow/dags/google_trends_dag.py", line 74, in <module>
    dag_creator = GooogleTrendsMonthly()
  File "/opt/airflow/dags/google_trends_dag.py", line 41, in __init__
    self.dag:DAG = self.create_dag()
  File "/opt/airflow/dags/google_trends_dag.py", line 54, in create_dag
    update_monthly: PythonOperator = PythonOperator(
  File "/home/airflow/.local/lib/python3.9/site-packages/airflow/models/baseoperator.py", line 429, in apply_defaults
    result = func(self, **kwargs, default_args=default_args)
  File "/home/airflow/.local/lib/python3.9/site-packages/airflow/operators/python.py", line 168, in __init__
    raise AirflowException("`python_callable` param must be callable")
airflow.exceptions.AirflowException: `python_callable` param must be callable
[2023-07-29T22:40:02.441+0300] {processor.py:811} WARNING - No viable dags retrieved from /opt/airflow/dags/google_trends_dag.py
[2023-07-29T22:40:02.478+0300] {processor.py:178} INFO - Processing /opt/airflow/dags/google_trends_dag.py took 0.066 seconds
[2023-07-29T22:40:32.583+0300] {processor.py:156} INFO - Started process (PID=115) to work on /opt/airflow/dags/google_trends_dag.py
[2023-07-29T22:40:32.584+0300] {processor.py:799} INFO - Processing file /opt/airflow/dags/google_trends_dag.py for tasks to queue
[2023-07-29T22:40:32.584+0300] {logging_mixin.py:149} INFO - [2023-07-29T22:40:32.584+0300] {dagbag.py:541} INFO - Filling up the DagBag from /opt/airflow/dags/google_trends_dag.py
[2023-07-29T22:40:32.598+0300] {logging_mixin.py:149} INFO - [2023-07-29T22:40:32.596+0300] {dagbag.py:350} ERROR - Failed to import: /opt/airflow/dags/google_trends_dag.py
Traceback (most recent call last):
  File "/home/airflow/.local/lib/python3.9/site-packages/airflow/models/dagbag.py", line 346, in parse
    loader.exec_module(new_module)
  File "<frozen importlib._bootstrap_external>", line 850, in exec_module
  File "<frozen importlib._bootstrap>", line 228, in _call_with_frames_removed
  File "/opt/airflow/dags/google_trends_dag.py", line 74, in <module>
    dag_creator = GooogleTrendsMonthly()
  File "/opt/airflow/dags/google_trends_dag.py", line 41, in __init__
    self.dag:DAG = self.create_dag()
  File "/opt/airflow/dags/google_trends_dag.py", line 54, in create_dag
    update_monthly: PythonOperator = PythonOperator(
  File "/home/airflow/.local/lib/python3.9/site-packages/airflow/models/baseoperator.py", line 429, in apply_defaults
    result = func(self, **kwargs, default_args=default_args)
  File "/home/airflow/.local/lib/python3.9/site-packages/airflow/operators/python.py", line 168, in __init__
    raise AirflowException("`python_callable` param must be callable")
airflow.exceptions.AirflowException: `python_callable` param must be callable
[2023-07-29T22:40:32.598+0300] {processor.py:811} WARNING - No viable dags retrieved from /opt/airflow/dags/google_trends_dag.py
[2023-07-29T22:40:32.623+0300] {processor.py:178} INFO - Processing /opt/airflow/dags/google_trends_dag.py took 0.044 seconds
[2023-07-29T22:41:02.770+0300] {processor.py:156} INFO - Started process (PID=123) to work on /opt/airflow/dags/google_trends_dag.py
[2023-07-29T22:41:02.771+0300] {processor.py:799} INFO - Processing file /opt/airflow/dags/google_trends_dag.py for tasks to queue
[2023-07-29T22:41:02.772+0300] {logging_mixin.py:149} INFO - [2023-07-29T22:41:02.772+0300] {dagbag.py:541} INFO - Filling up the DagBag from /opt/airflow/dags/google_trends_dag.py
[2023-07-29T22:41:02.789+0300] {logging_mixin.py:149} INFO - [2023-07-29T22:41:02.787+0300] {dagbag.py:350} ERROR - Failed to import: /opt/airflow/dags/google_trends_dag.py
Traceback (most recent call last):
  File "/home/airflow/.local/lib/python3.9/site-packages/airflow/models/dagbag.py", line 346, in parse
    loader.exec_module(new_module)
  File "<frozen importlib._bootstrap_external>", line 850, in exec_module
  File "<frozen importlib._bootstrap>", line 228, in _call_with_frames_removed
  File "/opt/airflow/dags/google_trends_dag.py", line 74, in <module>
    dag_creator = GooogleTrendsMonthly()
  File "/opt/airflow/dags/google_trends_dag.py", line 41, in __init__
    self.dag:DAG = self.create_dag()
  File "/opt/airflow/dags/google_trends_dag.py", line 54, in create_dag
    update_monthly: PythonOperator = PythonOperator(
  File "/home/airflow/.local/lib/python3.9/site-packages/airflow/models/baseoperator.py", line 429, in apply_defaults
    result = func(self, **kwargs, default_args=default_args)
  File "/home/airflow/.local/lib/python3.9/site-packages/airflow/operators/python.py", line 168, in __init__
    raise AirflowException("`python_callable` param must be callable")
airflow.exceptions.AirflowException: `python_callable` param must be callable
[2023-07-29T22:41:02.789+0300] {processor.py:811} WARNING - No viable dags retrieved from /opt/airflow/dags/google_trends_dag.py
[2023-07-29T22:41:02.814+0300] {processor.py:178} INFO - Processing /opt/airflow/dags/google_trends_dag.py took 0.048 seconds
[2023-07-29T22:42:15.207+0300] {processor.py:156} INFO - Started process (PID=27) to work on /opt/airflow/dags/google_trends_dag.py
[2023-07-29T22:42:15.208+0300] {processor.py:799} INFO - Processing file /opt/airflow/dags/google_trends_dag.py for tasks to queue
[2023-07-29T22:42:15.209+0300] {logging_mixin.py:149} INFO - [2023-07-29T22:42:15.209+0300] {dagbag.py:541} INFO - Filling up the DagBag from /opt/airflow/dags/google_trends_dag.py
[2023-07-29T22:42:15.226+0300] {logging_mixin.py:149} INFO - [2023-07-29T22:42:15.224+0300] {dagbag.py:350} ERROR - Failed to import: /opt/airflow/dags/google_trends_dag.py
Traceback (most recent call last):
  File "/home/airflow/.local/lib/python3.9/site-packages/airflow/models/dagbag.py", line 346, in parse
    loader.exec_module(new_module)
  File "<frozen importlib._bootstrap_external>", line 850, in exec_module
  File "<frozen importlib._bootstrap>", line 228, in _call_with_frames_removed
  File "/opt/airflow/dags/google_trends_dag.py", line 74, in <module>
    dag_creator = GooogleTrendsMonthly()
  File "/opt/airflow/dags/google_trends_dag.py", line 41, in __init__
    self.dag:DAG = self.create_dag()
  File "/opt/airflow/dags/google_trends_dag.py", line 54, in create_dag
    update_monthly: PythonOperator = PythonOperator(
  File "/home/airflow/.local/lib/python3.9/site-packages/airflow/models/baseoperator.py", line 429, in apply_defaults
    result = func(self, **kwargs, default_args=default_args)
  File "/home/airflow/.local/lib/python3.9/site-packages/airflow/operators/python.py", line 168, in __init__
    raise AirflowException("`python_callable` param must be callable")
airflow.exceptions.AirflowException: `python_callable` param must be callable
[2023-07-29T22:42:15.227+0300] {processor.py:811} WARNING - No viable dags retrieved from /opt/airflow/dags/google_trends_dag.py
[2023-07-29T22:42:15.246+0300] {processor.py:178} INFO - Processing /opt/airflow/dags/google_trends_dag.py took 0.043 seconds
[2023-07-29T22:42:45.392+0300] {processor.py:156} INFO - Started process (PID=35) to work on /opt/airflow/dags/google_trends_dag.py
[2023-07-29T22:42:45.404+0300] {processor.py:799} INFO - Processing file /opt/airflow/dags/google_trends_dag.py for tasks to queue
[2023-07-29T22:42:45.406+0300] {logging_mixin.py:149} INFO - [2023-07-29T22:42:45.406+0300] {dagbag.py:541} INFO - Filling up the DagBag from /opt/airflow/dags/google_trends_dag.py
[2023-07-29T22:42:45.424+0300] {logging_mixin.py:149} INFO - [2023-07-29T22:42:45.423+0300] {dagbag.py:350} ERROR - Failed to import: /opt/airflow/dags/google_trends_dag.py
Traceback (most recent call last):
  File "/home/airflow/.local/lib/python3.9/site-packages/airflow/models/dagbag.py", line 346, in parse
    loader.exec_module(new_module)
  File "<frozen importlib._bootstrap_external>", line 850, in exec_module
  File "<frozen importlib._bootstrap>", line 228, in _call_with_frames_removed
  File "/opt/airflow/dags/google_trends_dag.py", line 74, in <module>
    dag_creator = GooogleTrendsMonthly()
  File "/opt/airflow/dags/google_trends_dag.py", line 41, in __init__
    self.dag:DAG = self.create_dag()
  File "/opt/airflow/dags/google_trends_dag.py", line 54, in create_dag
    update_monthly: PythonOperator = PythonOperator(
  File "/home/airflow/.local/lib/python3.9/site-packages/airflow/models/baseoperator.py", line 429, in apply_defaults
    result = func(self, **kwargs, default_args=default_args)
  File "/home/airflow/.local/lib/python3.9/site-packages/airflow/operators/python.py", line 168, in __init__
    raise AirflowException("`python_callable` param must be callable")
airflow.exceptions.AirflowException: `python_callable` param must be callable
[2023-07-29T22:42:45.425+0300] {processor.py:811} WARNING - No viable dags retrieved from /opt/airflow/dags/google_trends_dag.py
[2023-07-29T22:42:45.451+0300] {processor.py:178} INFO - Processing /opt/airflow/dags/google_trends_dag.py took 0.062 seconds
[2023-07-29T22:43:15.571+0300] {processor.py:156} INFO - Started process (PID=43) to work on /opt/airflow/dags/google_trends_dag.py
[2023-07-29T22:43:15.571+0300] {processor.py:799} INFO - Processing file /opt/airflow/dags/google_trends_dag.py for tasks to queue
[2023-07-29T22:43:15.572+0300] {logging_mixin.py:149} INFO - [2023-07-29T22:43:15.572+0300] {dagbag.py:541} INFO - Filling up the DagBag from /opt/airflow/dags/google_trends_dag.py
[2023-07-29T22:43:15.588+0300] {logging_mixin.py:149} INFO - [2023-07-29T22:43:15.586+0300] {dagbag.py:350} ERROR - Failed to import: /opt/airflow/dags/google_trends_dag.py
Traceback (most recent call last):
  File "/home/airflow/.local/lib/python3.9/site-packages/airflow/models/dagbag.py", line 346, in parse
    loader.exec_module(new_module)
  File "<frozen importlib._bootstrap_external>", line 850, in exec_module
  File "<frozen importlib._bootstrap>", line 228, in _call_with_frames_removed
  File "/opt/airflow/dags/google_trends_dag.py", line 74, in <module>
    dag_creator = GooogleTrendsMonthly()
  File "/opt/airflow/dags/google_trends_dag.py", line 41, in __init__
    self.dag:DAG = self.create_dag()
  File "/opt/airflow/dags/google_trends_dag.py", line 54, in create_dag
    update_monthly: PythonOperator = PythonOperator(
  File "/home/airflow/.local/lib/python3.9/site-packages/airflow/models/baseoperator.py", line 429, in apply_defaults
    result = func(self, **kwargs, default_args=default_args)
  File "/home/airflow/.local/lib/python3.9/site-packages/airflow/operators/python.py", line 168, in __init__
    raise AirflowException("`python_callable` param must be callable")
airflow.exceptions.AirflowException: `python_callable` param must be callable
[2023-07-29T22:43:15.588+0300] {processor.py:811} WARNING - No viable dags retrieved from /opt/airflow/dags/google_trends_dag.py
[2023-07-29T22:43:15.610+0300] {processor.py:178} INFO - Processing /opt/airflow/dags/google_trends_dag.py took 0.044 seconds
[2023-07-29T22:43:45.747+0300] {processor.py:156} INFO - Started process (PID=51) to work on /opt/airflow/dags/google_trends_dag.py
[2023-07-29T22:43:45.748+0300] {processor.py:799} INFO - Processing file /opt/airflow/dags/google_trends_dag.py for tasks to queue
[2023-07-29T22:43:45.749+0300] {logging_mixin.py:149} INFO - [2023-07-29T22:43:45.749+0300] {dagbag.py:541} INFO - Filling up the DagBag from /opt/airflow/dags/google_trends_dag.py
[2023-07-29T22:43:45.768+0300] {logging_mixin.py:149} INFO - [2023-07-29T22:43:45.765+0300] {dagbag.py:350} ERROR - Failed to import: /opt/airflow/dags/google_trends_dag.py
Traceback (most recent call last):
  File "/home/airflow/.local/lib/python3.9/site-packages/airflow/models/dagbag.py", line 346, in parse
    loader.exec_module(new_module)
  File "<frozen importlib._bootstrap_external>", line 850, in exec_module
  File "<frozen importlib._bootstrap>", line 228, in _call_with_frames_removed
  File "/opt/airflow/dags/google_trends_dag.py", line 74, in <module>
    dag_creator = GooogleTrendsMonthly()
  File "/opt/airflow/dags/google_trends_dag.py", line 41, in __init__
    self.dag:DAG = self.create_dag()
  File "/opt/airflow/dags/google_trends_dag.py", line 54, in create_dag
    update_monthly: PythonOperator = PythonOperator(
  File "/home/airflow/.local/lib/python3.9/site-packages/airflow/models/baseoperator.py", line 429, in apply_defaults
    result = func(self, **kwargs, default_args=default_args)
  File "/home/airflow/.local/lib/python3.9/site-packages/airflow/operators/python.py", line 168, in __init__
    raise AirflowException("`python_callable` param must be callable")
airflow.exceptions.AirflowException: `python_callable` param must be callable
[2023-07-29T22:43:45.769+0300] {processor.py:811} WARNING - No viable dags retrieved from /opt/airflow/dags/google_trends_dag.py
[2023-07-29T22:43:45.798+0300] {processor.py:178} INFO - Processing /opt/airflow/dags/google_trends_dag.py took 0.054 seconds
[2023-07-29T22:44:15.908+0300] {processor.py:156} INFO - Started process (PID=59) to work on /opt/airflow/dags/google_trends_dag.py
[2023-07-29T22:44:15.909+0300] {processor.py:799} INFO - Processing file /opt/airflow/dags/google_trends_dag.py for tasks to queue
[2023-07-29T22:44:15.910+0300] {logging_mixin.py:149} INFO - [2023-07-29T22:44:15.910+0300] {dagbag.py:541} INFO - Filling up the DagBag from /opt/airflow/dags/google_trends_dag.py
[2023-07-29T22:44:15.929+0300] {logging_mixin.py:149} INFO - [2023-07-29T22:44:15.927+0300] {dagbag.py:350} ERROR - Failed to import: /opt/airflow/dags/google_trends_dag.py
Traceback (most recent call last):
  File "/home/airflow/.local/lib/python3.9/site-packages/airflow/models/dagbag.py", line 346, in parse
    loader.exec_module(new_module)
  File "<frozen importlib._bootstrap_external>", line 850, in exec_module
  File "<frozen importlib._bootstrap>", line 228, in _call_with_frames_removed
  File "/opt/airflow/dags/google_trends_dag.py", line 74, in <module>
    dag_creator = GooogleTrendsMonthly()
  File "/opt/airflow/dags/google_trends_dag.py", line 41, in __init__
    self.dag:DAG = self.create_dag()
  File "/opt/airflow/dags/google_trends_dag.py", line 54, in create_dag
    update_monthly: PythonOperator = PythonOperator(
  File "/home/airflow/.local/lib/python3.9/site-packages/airflow/models/baseoperator.py", line 429, in apply_defaults
    result = func(self, **kwargs, default_args=default_args)
  File "/home/airflow/.local/lib/python3.9/site-packages/airflow/operators/python.py", line 168, in __init__
    raise AirflowException("`python_callable` param must be callable")
airflow.exceptions.AirflowException: `python_callable` param must be callable
[2023-07-29T22:44:15.930+0300] {processor.py:811} WARNING - No viable dags retrieved from /opt/airflow/dags/google_trends_dag.py
[2023-07-29T22:44:15.960+0300] {processor.py:178} INFO - Processing /opt/airflow/dags/google_trends_dag.py took 0.055 seconds
[2023-07-29T22:44:46.106+0300] {processor.py:156} INFO - Started process (PID=67) to work on /opt/airflow/dags/google_trends_dag.py
[2023-07-29T22:44:46.107+0300] {processor.py:799} INFO - Processing file /opt/airflow/dags/google_trends_dag.py for tasks to queue
[2023-07-29T22:44:46.107+0300] {logging_mixin.py:149} INFO - [2023-07-29T22:44:46.107+0300] {dagbag.py:541} INFO - Filling up the DagBag from /opt/airflow/dags/google_trends_dag.py
[2023-07-29T22:44:46.120+0300] {logging_mixin.py:149} INFO - [2023-07-29T22:44:46.119+0300] {dagbag.py:350} ERROR - Failed to import: /opt/airflow/dags/google_trends_dag.py
Traceback (most recent call last):
  File "/home/airflow/.local/lib/python3.9/site-packages/airflow/models/dagbag.py", line 346, in parse
    loader.exec_module(new_module)
  File "<frozen importlib._bootstrap_external>", line 850, in exec_module
  File "<frozen importlib._bootstrap>", line 228, in _call_with_frames_removed
  File "/opt/airflow/dags/google_trends_dag.py", line 74, in <module>
    dag_creator = GooogleTrendsMonthly()
  File "/opt/airflow/dags/google_trends_dag.py", line 41, in __init__
    self.dag:DAG = self.create_dag()
  File "/opt/airflow/dags/google_trends_dag.py", line 54, in create_dag
    update_monthly: PythonOperator = PythonOperator(
  File "/home/airflow/.local/lib/python3.9/site-packages/airflow/models/baseoperator.py", line 429, in apply_defaults
    result = func(self, **kwargs, default_args=default_args)
  File "/home/airflow/.local/lib/python3.9/site-packages/airflow/operators/python.py", line 168, in __init__
    raise AirflowException("`python_callable` param must be callable")
airflow.exceptions.AirflowException: `python_callable` param must be callable
[2023-07-29T22:44:46.121+0300] {processor.py:811} WARNING - No viable dags retrieved from /opt/airflow/dags/google_trends_dag.py
[2023-07-29T22:44:46.145+0300] {processor.py:178} INFO - Processing /opt/airflow/dags/google_trends_dag.py took 0.043 seconds
[2023-07-29T22:45:16.298+0300] {processor.py:156} INFO - Started process (PID=76) to work on /opt/airflow/dags/google_trends_dag.py
[2023-07-29T22:45:16.299+0300] {processor.py:799} INFO - Processing file /opt/airflow/dags/google_trends_dag.py for tasks to queue
[2023-07-29T22:45:16.299+0300] {logging_mixin.py:149} INFO - [2023-07-29T22:45:16.299+0300] {dagbag.py:541} INFO - Filling up the DagBag from /opt/airflow/dags/google_trends_dag.py
[2023-07-29T22:45:16.313+0300] {logging_mixin.py:149} INFO - [2023-07-29T22:45:16.311+0300] {dagbag.py:350} ERROR - Failed to import: /opt/airflow/dags/google_trends_dag.py
Traceback (most recent call last):
  File "/home/airflow/.local/lib/python3.9/site-packages/airflow/models/dagbag.py", line 346, in parse
    loader.exec_module(new_module)
  File "<frozen importlib._bootstrap_external>", line 850, in exec_module
  File "<frozen importlib._bootstrap>", line 228, in _call_with_frames_removed
  File "/opt/airflow/dags/google_trends_dag.py", line 74, in <module>
    dag_creator = GooogleTrendsMonthly()
  File "/opt/airflow/dags/google_trends_dag.py", line 41, in __init__
    self.dag:DAG = self.create_dag()
  File "/opt/airflow/dags/google_trends_dag.py", line 54, in create_dag
    update_monthly: PythonOperator = PythonOperator(
  File "/home/airflow/.local/lib/python3.9/site-packages/airflow/models/baseoperator.py", line 429, in apply_defaults
    result = func(self, **kwargs, default_args=default_args)
  File "/home/airflow/.local/lib/python3.9/site-packages/airflow/operators/python.py", line 168, in __init__
    raise AirflowException("`python_callable` param must be callable")
airflow.exceptions.AirflowException: `python_callable` param must be callable
[2023-07-29T22:45:16.313+0300] {processor.py:811} WARNING - No viable dags retrieved from /opt/airflow/dags/google_trends_dag.py
[2023-07-29T22:45:16.343+0300] {processor.py:178} INFO - Processing /opt/airflow/dags/google_trends_dag.py took 0.048 seconds
[2023-07-29T22:45:46.458+0300] {processor.py:156} INFO - Started process (PID=85) to work on /opt/airflow/dags/google_trends_dag.py
[2023-07-29T22:45:46.459+0300] {processor.py:799} INFO - Processing file /opt/airflow/dags/google_trends_dag.py for tasks to queue
[2023-07-29T22:45:46.460+0300] {logging_mixin.py:149} INFO - [2023-07-29T22:45:46.459+0300] {dagbag.py:541} INFO - Filling up the DagBag from /opt/airflow/dags/google_trends_dag.py
[2023-07-29T22:45:46.473+0300] {logging_mixin.py:149} INFO - [2023-07-29T22:45:46.471+0300] {dagbag.py:350} ERROR - Failed to import: /opt/airflow/dags/google_trends_dag.py
Traceback (most recent call last):
  File "/home/airflow/.local/lib/python3.9/site-packages/airflow/models/dagbag.py", line 346, in parse
    loader.exec_module(new_module)
  File "<frozen importlib._bootstrap_external>", line 850, in exec_module
  File "<frozen importlib._bootstrap>", line 228, in _call_with_frames_removed
  File "/opt/airflow/dags/google_trends_dag.py", line 74, in <module>
    dag_creator = GooogleTrendsMonthly()
  File "/opt/airflow/dags/google_trends_dag.py", line 41, in __init__
    self.dag:DAG = self.create_dag()
  File "/opt/airflow/dags/google_trends_dag.py", line 54, in create_dag
    update_monthly: PythonOperator = PythonOperator(
  File "/home/airflow/.local/lib/python3.9/site-packages/airflow/models/baseoperator.py", line 429, in apply_defaults
    result = func(self, **kwargs, default_args=default_args)
  File "/home/airflow/.local/lib/python3.9/site-packages/airflow/operators/python.py", line 168, in __init__
    raise AirflowException("`python_callable` param must be callable")
airflow.exceptions.AirflowException: `python_callable` param must be callable
[2023-07-29T22:45:46.473+0300] {processor.py:811} WARNING - No viable dags retrieved from /opt/airflow/dags/google_trends_dag.py
[2023-07-29T22:45:46.501+0300] {processor.py:178} INFO - Processing /opt/airflow/dags/google_trends_dag.py took 0.047 seconds
[2023-07-29T22:46:16.658+0300] {processor.py:156} INFO - Started process (PID=93) to work on /opt/airflow/dags/google_trends_dag.py
[2023-07-29T22:46:16.659+0300] {processor.py:799} INFO - Processing file /opt/airflow/dags/google_trends_dag.py for tasks to queue
[2023-07-29T22:46:16.660+0300] {logging_mixin.py:149} INFO - [2023-07-29T22:46:16.660+0300] {dagbag.py:541} INFO - Filling up the DagBag from /opt/airflow/dags/google_trends_dag.py
[2023-07-29T22:46:16.700+0300] {logging_mixin.py:149} INFO - [2023-07-29T22:46:16.695+0300] {dagbag.py:350} ERROR - Failed to import: /opt/airflow/dags/google_trends_dag.py
Traceback (most recent call last):
  File "/home/airflow/.local/lib/python3.9/site-packages/airflow/models/dagbag.py", line 346, in parse
    loader.exec_module(new_module)
  File "<frozen importlib._bootstrap_external>", line 850, in exec_module
  File "<frozen importlib._bootstrap>", line 228, in _call_with_frames_removed
  File "/opt/airflow/dags/google_trends_dag.py", line 74, in <module>
    dag_creator = GooogleTrendsMonthly()
  File "/opt/airflow/dags/google_trends_dag.py", line 41, in __init__
    self.dag:DAG = self.create_dag()
  File "/opt/airflow/dags/google_trends_dag.py", line 54, in create_dag
    update_monthly: PythonOperator = PythonOperator(
  File "/home/airflow/.local/lib/python3.9/site-packages/airflow/models/baseoperator.py", line 429, in apply_defaults
    result = func(self, **kwargs, default_args=default_args)
  File "/home/airflow/.local/lib/python3.9/site-packages/airflow/operators/python.py", line 168, in __init__
    raise AirflowException("`python_callable` param must be callable")
airflow.exceptions.AirflowException: `python_callable` param must be callable
[2023-07-29T22:46:16.703+0300] {processor.py:811} WARNING - No viable dags retrieved from /opt/airflow/dags/google_trends_dag.py
[2023-07-29T22:46:16.737+0300] {processor.py:178} INFO - Processing /opt/airflow/dags/google_trends_dag.py took 0.086 seconds
[2023-07-29T22:46:46.834+0300] {processor.py:156} INFO - Started process (PID=100) to work on /opt/airflow/dags/google_trends_dag.py
[2023-07-29T22:46:46.835+0300] {processor.py:799} INFO - Processing file /opt/airflow/dags/google_trends_dag.py for tasks to queue
[2023-07-29T22:46:46.837+0300] {logging_mixin.py:149} INFO - [2023-07-29T22:46:46.836+0300] {dagbag.py:541} INFO - Filling up the DagBag from /opt/airflow/dags/google_trends_dag.py
[2023-07-29T22:46:46.863+0300] {logging_mixin.py:149} INFO - [2023-07-29T22:46:46.861+0300] {dagbag.py:350} ERROR - Failed to import: /opt/airflow/dags/google_trends_dag.py
Traceback (most recent call last):
  File "/home/airflow/.local/lib/python3.9/site-packages/airflow/models/dagbag.py", line 346, in parse
    loader.exec_module(new_module)
  File "<frozen importlib._bootstrap_external>", line 850, in exec_module
  File "<frozen importlib._bootstrap>", line 228, in _call_with_frames_removed
  File "/opt/airflow/dags/google_trends_dag.py", line 74, in <module>
    dag_creator = GooogleTrendsMonthly()
  File "/opt/airflow/dags/google_trends_dag.py", line 41, in __init__
    self.dag:DAG = self.create_dag()
  File "/opt/airflow/dags/google_trends_dag.py", line 54, in create_dag
    update_monthly: PythonOperator = PythonOperator(
  File "/home/airflow/.local/lib/python3.9/site-packages/airflow/models/baseoperator.py", line 429, in apply_defaults
    result = func(self, **kwargs, default_args=default_args)
  File "/home/airflow/.local/lib/python3.9/site-packages/airflow/operators/python.py", line 168, in __init__
    raise AirflowException("`python_callable` param must be callable")
airflow.exceptions.AirflowException: `python_callable` param must be callable
[2023-07-29T22:46:46.864+0300] {processor.py:811} WARNING - No viable dags retrieved from /opt/airflow/dags/google_trends_dag.py
[2023-07-29T22:46:46.900+0300] {processor.py:178} INFO - Processing /opt/airflow/dags/google_trends_dag.py took 0.073 seconds
[2023-07-29T22:47:17.045+0300] {processor.py:156} INFO - Started process (PID=108) to work on /opt/airflow/dags/google_trends_dag.py
[2023-07-29T22:47:17.046+0300] {processor.py:799} INFO - Processing file /opt/airflow/dags/google_trends_dag.py for tasks to queue
[2023-07-29T22:47:17.048+0300] {logging_mixin.py:149} INFO - [2023-07-29T22:47:17.047+0300] {dagbag.py:541} INFO - Filling up the DagBag from /opt/airflow/dags/google_trends_dag.py
[2023-07-29T22:47:17.074+0300] {logging_mixin.py:149} INFO - [2023-07-29T22:47:17.071+0300] {dagbag.py:350} ERROR - Failed to import: /opt/airflow/dags/google_trends_dag.py
Traceback (most recent call last):
  File "/home/airflow/.local/lib/python3.9/site-packages/airflow/models/dagbag.py", line 346, in parse
    loader.exec_module(new_module)
  File "<frozen importlib._bootstrap_external>", line 850, in exec_module
  File "<frozen importlib._bootstrap>", line 228, in _call_with_frames_removed
  File "/opt/airflow/dags/google_trends_dag.py", line 74, in <module>
    dag_creator = GooogleTrendsMonthly()
  File "/opt/airflow/dags/google_trends_dag.py", line 41, in __init__
    self.dag:DAG = self.create_dag()
  File "/opt/airflow/dags/google_trends_dag.py", line 54, in create_dag
    update_monthly: PythonOperator = PythonOperator(
  File "/home/airflow/.local/lib/python3.9/site-packages/airflow/models/baseoperator.py", line 429, in apply_defaults
    result = func(self, **kwargs, default_args=default_args)
  File "/home/airflow/.local/lib/python3.9/site-packages/airflow/operators/python.py", line 168, in __init__
    raise AirflowException("`python_callable` param must be callable")
airflow.exceptions.AirflowException: `python_callable` param must be callable
[2023-07-29T22:47:17.074+0300] {processor.py:811} WARNING - No viable dags retrieved from /opt/airflow/dags/google_trends_dag.py
[2023-07-29T22:47:17.106+0300] {processor.py:178} INFO - Processing /opt/airflow/dags/google_trends_dag.py took 0.065 seconds
[2023-07-29T22:47:47.219+0300] {processor.py:156} INFO - Started process (PID=116) to work on /opt/airflow/dags/google_trends_dag.py
[2023-07-29T22:47:47.220+0300] {processor.py:799} INFO - Processing file /opt/airflow/dags/google_trends_dag.py for tasks to queue
[2023-07-29T22:47:47.221+0300] {logging_mixin.py:149} INFO - [2023-07-29T22:47:47.221+0300] {dagbag.py:541} INFO - Filling up the DagBag from /opt/airflow/dags/google_trends_dag.py
[2023-07-29T22:47:47.244+0300] {logging_mixin.py:149} INFO - [2023-07-29T22:47:47.242+0300] {dagbag.py:350} ERROR - Failed to import: /opt/airflow/dags/google_trends_dag.py
Traceback (most recent call last):
  File "/home/airflow/.local/lib/python3.9/site-packages/airflow/models/dagbag.py", line 346, in parse
    loader.exec_module(new_module)
  File "<frozen importlib._bootstrap_external>", line 850, in exec_module
  File "<frozen importlib._bootstrap>", line 228, in _call_with_frames_removed
  File "/opt/airflow/dags/google_trends_dag.py", line 74, in <module>
    dag_creator = GooogleTrendsMonthly()
  File "/opt/airflow/dags/google_trends_dag.py", line 41, in __init__
    self.dag:DAG = self.create_dag()
  File "/opt/airflow/dags/google_trends_dag.py", line 54, in create_dag
    update_monthly: PythonOperator = PythonOperator(
  File "/home/airflow/.local/lib/python3.9/site-packages/airflow/models/baseoperator.py", line 429, in apply_defaults
    result = func(self, **kwargs, default_args=default_args)
  File "/home/airflow/.local/lib/python3.9/site-packages/airflow/operators/python.py", line 168, in __init__
    raise AirflowException("`python_callable` param must be callable")
airflow.exceptions.AirflowException: `python_callable` param must be callable
[2023-07-29T22:47:47.245+0300] {processor.py:811} WARNING - No viable dags retrieved from /opt/airflow/dags/google_trends_dag.py
[2023-07-29T22:47:47.275+0300] {processor.py:178} INFO - Processing /opt/airflow/dags/google_trends_dag.py took 0.061 seconds
[2023-07-29T22:48:17.406+0300] {processor.py:156} INFO - Started process (PID=124) to work on /opt/airflow/dags/google_trends_dag.py
[2023-07-29T22:48:17.408+0300] {processor.py:799} INFO - Processing file /opt/airflow/dags/google_trends_dag.py for tasks to queue
[2023-07-29T22:48:17.408+0300] {logging_mixin.py:149} INFO - [2023-07-29T22:48:17.408+0300] {dagbag.py:541} INFO - Filling up the DagBag from /opt/airflow/dags/google_trends_dag.py
[2023-07-29T22:48:17.428+0300] {logging_mixin.py:149} INFO - [2023-07-29T22:48:17.425+0300] {dagbag.py:350} ERROR - Failed to import: /opt/airflow/dags/google_trends_dag.py
Traceback (most recent call last):
  File "/home/airflow/.local/lib/python3.9/site-packages/airflow/models/dagbag.py", line 346, in parse
    loader.exec_module(new_module)
  File "<frozen importlib._bootstrap_external>", line 850, in exec_module
  File "<frozen importlib._bootstrap>", line 228, in _call_with_frames_removed
  File "/opt/airflow/dags/google_trends_dag.py", line 74, in <module>
    dag_creator = GooogleTrendsMonthly()
  File "/opt/airflow/dags/google_trends_dag.py", line 41, in __init__
    self.dag:DAG = self.create_dag()
  File "/opt/airflow/dags/google_trends_dag.py", line 54, in create_dag
    update_monthly: PythonOperator = PythonOperator(
  File "/home/airflow/.local/lib/python3.9/site-packages/airflow/models/baseoperator.py", line 429, in apply_defaults
    result = func(self, **kwargs, default_args=default_args)
  File "/home/airflow/.local/lib/python3.9/site-packages/airflow/operators/python.py", line 168, in __init__
    raise AirflowException("`python_callable` param must be callable")
airflow.exceptions.AirflowException: `python_callable` param must be callable
[2023-07-29T22:48:17.428+0300] {processor.py:811} WARNING - No viable dags retrieved from /opt/airflow/dags/google_trends_dag.py
[2023-07-29T22:48:17.458+0300] {processor.py:178} INFO - Processing /opt/airflow/dags/google_trends_dag.py took 0.054 seconds
[2023-07-29T22:48:47.607+0300] {processor.py:156} INFO - Started process (PID=133) to work on /opt/airflow/dags/google_trends_dag.py
[2023-07-29T22:48:47.608+0300] {processor.py:799} INFO - Processing file /opt/airflow/dags/google_trends_dag.py for tasks to queue
[2023-07-29T22:48:47.609+0300] {logging_mixin.py:149} INFO - [2023-07-29T22:48:47.609+0300] {dagbag.py:541} INFO - Filling up the DagBag from /opt/airflow/dags/google_trends_dag.py
[2023-07-29T22:48:47.628+0300] {logging_mixin.py:149} INFO - [2023-07-29T22:48:47.627+0300] {dagbag.py:350} ERROR - Failed to import: /opt/airflow/dags/google_trends_dag.py
Traceback (most recent call last):
  File "/home/airflow/.local/lib/python3.9/site-packages/airflow/models/dagbag.py", line 346, in parse
    loader.exec_module(new_module)
  File "<frozen importlib._bootstrap_external>", line 850, in exec_module
  File "<frozen importlib._bootstrap>", line 228, in _call_with_frames_removed
  File "/opt/airflow/dags/google_trends_dag.py", line 74, in <module>
    dag_creator = GooogleTrendsMonthly()
  File "/opt/airflow/dags/google_trends_dag.py", line 41, in __init__
    self.dag:DAG = self.create_dag()
  File "/opt/airflow/dags/google_trends_dag.py", line 54, in create_dag
    update_monthly: PythonOperator = PythonOperator(
  File "/home/airflow/.local/lib/python3.9/site-packages/airflow/models/baseoperator.py", line 429, in apply_defaults
    result = func(self, **kwargs, default_args=default_args)
  File "/home/airflow/.local/lib/python3.9/site-packages/airflow/operators/python.py", line 168, in __init__
    raise AirflowException("`python_callable` param must be callable")
airflow.exceptions.AirflowException: `python_callable` param must be callable
[2023-07-29T22:48:47.629+0300] {processor.py:811} WARNING - No viable dags retrieved from /opt/airflow/dags/google_trends_dag.py
[2023-07-29T22:48:47.660+0300] {processor.py:178} INFO - Processing /opt/airflow/dags/google_trends_dag.py took 0.058 seconds
[2023-07-29T22:49:17.776+0300] {processor.py:156} INFO - Started process (PID=142) to work on /opt/airflow/dags/google_trends_dag.py
[2023-07-29T22:49:17.777+0300] {processor.py:799} INFO - Processing file /opt/airflow/dags/google_trends_dag.py for tasks to queue
[2023-07-29T22:49:17.777+0300] {logging_mixin.py:149} INFO - [2023-07-29T22:49:17.777+0300] {dagbag.py:541} INFO - Filling up the DagBag from /opt/airflow/dags/google_trends_dag.py
[2023-07-29T22:49:17.790+0300] {logging_mixin.py:149} INFO - [2023-07-29T22:49:17.789+0300] {dagbag.py:350} ERROR - Failed to import: /opt/airflow/dags/google_trends_dag.py
Traceback (most recent call last):
  File "/home/airflow/.local/lib/python3.9/site-packages/airflow/models/dagbag.py", line 346, in parse
    loader.exec_module(new_module)
  File "<frozen importlib._bootstrap_external>", line 850, in exec_module
  File "<frozen importlib._bootstrap>", line 228, in _call_with_frames_removed
  File "/opt/airflow/dags/google_trends_dag.py", line 74, in <module>
    dag_creator = GooogleTrendsMonthly()
  File "/opt/airflow/dags/google_trends_dag.py", line 41, in __init__
    self.dag:DAG = self.create_dag()
  File "/opt/airflow/dags/google_trends_dag.py", line 54, in create_dag
    update_monthly: PythonOperator = PythonOperator(
  File "/home/airflow/.local/lib/python3.9/site-packages/airflow/models/baseoperator.py", line 429, in apply_defaults
    result = func(self, **kwargs, default_args=default_args)
  File "/home/airflow/.local/lib/python3.9/site-packages/airflow/operators/python.py", line 168, in __init__
    raise AirflowException("`python_callable` param must be callable")
airflow.exceptions.AirflowException: `python_callable` param must be callable
[2023-07-29T22:49:17.791+0300] {processor.py:811} WARNING - No viable dags retrieved from /opt/airflow/dags/google_trends_dag.py
[2023-07-29T22:49:17.819+0300] {processor.py:178} INFO - Processing /opt/airflow/dags/google_trends_dag.py took 0.046 seconds
[2023-07-29T22:49:47.952+0300] {processor.py:156} INFO - Started process (PID=150) to work on /opt/airflow/dags/google_trends_dag.py
[2023-07-29T22:49:47.953+0300] {processor.py:799} INFO - Processing file /opt/airflow/dags/google_trends_dag.py for tasks to queue
[2023-07-29T22:49:47.954+0300] {logging_mixin.py:149} INFO - [2023-07-29T22:49:47.954+0300] {dagbag.py:541} INFO - Filling up the DagBag from /opt/airflow/dags/google_trends_dag.py
[2023-07-29T22:49:47.970+0300] {logging_mixin.py:149} INFO - [2023-07-29T22:49:47.968+0300] {dagbag.py:350} ERROR - Failed to import: /opt/airflow/dags/google_trends_dag.py
Traceback (most recent call last):
  File "/home/airflow/.local/lib/python3.9/site-packages/airflow/models/dagbag.py", line 346, in parse
    loader.exec_module(new_module)
  File "<frozen importlib._bootstrap_external>", line 850, in exec_module
  File "<frozen importlib._bootstrap>", line 228, in _call_with_frames_removed
  File "/opt/airflow/dags/google_trends_dag.py", line 74, in <module>
    dag_creator = GooogleTrendsMonthly()
  File "/opt/airflow/dags/google_trends_dag.py", line 41, in __init__
    self.dag:DAG = self.create_dag()
  File "/opt/airflow/dags/google_trends_dag.py", line 54, in create_dag
    update_monthly: PythonOperator = PythonOperator(
  File "/home/airflow/.local/lib/python3.9/site-packages/airflow/models/baseoperator.py", line 429, in apply_defaults
    result = func(self, **kwargs, default_args=default_args)
  File "/home/airflow/.local/lib/python3.9/site-packages/airflow/operators/python.py", line 168, in __init__
    raise AirflowException("`python_callable` param must be callable")
airflow.exceptions.AirflowException: `python_callable` param must be callable
[2023-07-29T22:49:47.971+0300] {processor.py:811} WARNING - No viable dags retrieved from /opt/airflow/dags/google_trends_dag.py
[2023-07-29T22:49:47.994+0300] {processor.py:178} INFO - Processing /opt/airflow/dags/google_trends_dag.py took 0.045 seconds
[2023-07-29T22:50:18.116+0300] {processor.py:156} INFO - Started process (PID=158) to work on /opt/airflow/dags/google_trends_dag.py
[2023-07-29T22:50:18.117+0300] {processor.py:799} INFO - Processing file /opt/airflow/dags/google_trends_dag.py for tasks to queue
[2023-07-29T22:50:18.118+0300] {logging_mixin.py:149} INFO - [2023-07-29T22:50:18.118+0300] {dagbag.py:541} INFO - Filling up the DagBag from /opt/airflow/dags/google_trends_dag.py
[2023-07-29T22:50:18.137+0300] {logging_mixin.py:149} INFO - [2023-07-29T22:50:18.135+0300] {dagbag.py:350} ERROR - Failed to import: /opt/airflow/dags/google_trends_dag.py
Traceback (most recent call last):
  File "/home/airflow/.local/lib/python3.9/site-packages/airflow/models/dagbag.py", line 346, in parse
    loader.exec_module(new_module)
  File "<frozen importlib._bootstrap_external>", line 850, in exec_module
  File "<frozen importlib._bootstrap>", line 228, in _call_with_frames_removed
  File "/opt/airflow/dags/google_trends_dag.py", line 74, in <module>
    dag_creator = GooogleTrendsMonthly()
  File "/opt/airflow/dags/google_trends_dag.py", line 41, in __init__
    self.dag:DAG = self.create_dag()
  File "/opt/airflow/dags/google_trends_dag.py", line 54, in create_dag
    update_monthly: PythonOperator = PythonOperator(
  File "/home/airflow/.local/lib/python3.9/site-packages/airflow/models/baseoperator.py", line 429, in apply_defaults
    result = func(self, **kwargs, default_args=default_args)
  File "/home/airflow/.local/lib/python3.9/site-packages/airflow/operators/python.py", line 168, in __init__
    raise AirflowException("`python_callable` param must be callable")
airflow.exceptions.AirflowException: `python_callable` param must be callable
[2023-07-29T22:50:18.137+0300] {processor.py:811} WARNING - No viable dags retrieved from /opt/airflow/dags/google_trends_dag.py
[2023-07-29T22:50:18.160+0300] {processor.py:178} INFO - Processing /opt/airflow/dags/google_trends_dag.py took 0.048 seconds
[2023-07-29T22:50:48.305+0300] {processor.py:156} INFO - Started process (PID=166) to work on /opt/airflow/dags/google_trends_dag.py
[2023-07-29T22:50:48.306+0300] {processor.py:799} INFO - Processing file /opt/airflow/dags/google_trends_dag.py for tasks to queue
[2023-07-29T22:50:48.307+0300] {logging_mixin.py:149} INFO - [2023-07-29T22:50:48.307+0300] {dagbag.py:541} INFO - Filling up the DagBag from /opt/airflow/dags/google_trends_dag.py
[2023-07-29T22:50:48.325+0300] {logging_mixin.py:149} INFO - [2023-07-29T22:50:48.323+0300] {dagbag.py:350} ERROR - Failed to import: /opt/airflow/dags/google_trends_dag.py
Traceback (most recent call last):
  File "/home/airflow/.local/lib/python3.9/site-packages/airflow/models/dagbag.py", line 346, in parse
    loader.exec_module(new_module)
  File "<frozen importlib._bootstrap_external>", line 850, in exec_module
  File "<frozen importlib._bootstrap>", line 228, in _call_with_frames_removed
  File "/opt/airflow/dags/google_trends_dag.py", line 74, in <module>
    dag_creator = GooogleTrendsMonthly()
  File "/opt/airflow/dags/google_trends_dag.py", line 41, in __init__
    self.dag:DAG = self.create_dag()
  File "/opt/airflow/dags/google_trends_dag.py", line 54, in create_dag
    update_monthly: PythonOperator = PythonOperator(
  File "/home/airflow/.local/lib/python3.9/site-packages/airflow/models/baseoperator.py", line 429, in apply_defaults
    result = func(self, **kwargs, default_args=default_args)
  File "/home/airflow/.local/lib/python3.9/site-packages/airflow/operators/python.py", line 168, in __init__
    raise AirflowException("`python_callable` param must be callable")
airflow.exceptions.AirflowException: `python_callable` param must be callable
[2023-07-29T22:50:48.326+0300] {processor.py:811} WARNING - No viable dags retrieved from /opt/airflow/dags/google_trends_dag.py
[2023-07-29T22:50:48.351+0300] {processor.py:178} INFO - Processing /opt/airflow/dags/google_trends_dag.py took 0.050 seconds
[2023-07-29T22:51:18.472+0300] {processor.py:156} INFO - Started process (PID=174) to work on /opt/airflow/dags/google_trends_dag.py
[2023-07-29T22:51:18.473+0300] {processor.py:799} INFO - Processing file /opt/airflow/dags/google_trends_dag.py for tasks to queue
[2023-07-29T22:51:18.473+0300] {logging_mixin.py:149} INFO - [2023-07-29T22:51:18.473+0300] {dagbag.py:541} INFO - Filling up the DagBag from /opt/airflow/dags/google_trends_dag.py
[2023-07-29T22:51:18.488+0300] {logging_mixin.py:149} INFO - [2023-07-29T22:51:18.486+0300] {dagbag.py:350} ERROR - Failed to import: /opt/airflow/dags/google_trends_dag.py
Traceback (most recent call last):
  File "/home/airflow/.local/lib/python3.9/site-packages/airflow/models/dagbag.py", line 346, in parse
    loader.exec_module(new_module)
  File "<frozen importlib._bootstrap_external>", line 850, in exec_module
  File "<frozen importlib._bootstrap>", line 228, in _call_with_frames_removed
  File "/opt/airflow/dags/google_trends_dag.py", line 74, in <module>
    dag_creator = GooogleTrendsMonthly()
  File "/opt/airflow/dags/google_trends_dag.py", line 41, in __init__
    self.dag:DAG = self.create_dag()
  File "/opt/airflow/dags/google_trends_dag.py", line 54, in create_dag
    update_monthly: PythonOperator = PythonOperator(
  File "/home/airflow/.local/lib/python3.9/site-packages/airflow/models/baseoperator.py", line 429, in apply_defaults
    result = func(self, **kwargs, default_args=default_args)
  File "/home/airflow/.local/lib/python3.9/site-packages/airflow/operators/python.py", line 168, in __init__
    raise AirflowException("`python_callable` param must be callable")
airflow.exceptions.AirflowException: `python_callable` param must be callable
[2023-07-29T22:51:18.488+0300] {processor.py:811} WARNING - No viable dags retrieved from /opt/airflow/dags/google_trends_dag.py
[2023-07-29T22:51:18.508+0300] {processor.py:178} INFO - Processing /opt/airflow/dags/google_trends_dag.py took 0.040 seconds
[2023-07-29T22:51:48.642+0300] {processor.py:156} INFO - Started process (PID=182) to work on /opt/airflow/dags/google_trends_dag.py
[2023-07-29T22:51:48.644+0300] {processor.py:799} INFO - Processing file /opt/airflow/dags/google_trends_dag.py for tasks to queue
[2023-07-29T22:51:48.645+0300] {logging_mixin.py:149} INFO - [2023-07-29T22:51:48.644+0300] {dagbag.py:541} INFO - Filling up the DagBag from /opt/airflow/dags/google_trends_dag.py
[2023-07-29T22:51:48.666+0300] {logging_mixin.py:149} INFO - [2023-07-29T22:51:48.664+0300] {dagbag.py:350} ERROR - Failed to import: /opt/airflow/dags/google_trends_dag.py
Traceback (most recent call last):
  File "/home/airflow/.local/lib/python3.9/site-packages/airflow/models/dagbag.py", line 346, in parse
    loader.exec_module(new_module)
  File "<frozen importlib._bootstrap_external>", line 850, in exec_module
  File "<frozen importlib._bootstrap>", line 228, in _call_with_frames_removed
  File "/opt/airflow/dags/google_trends_dag.py", line 74, in <module>
    dag_creator = GooogleTrendsMonthly()
  File "/opt/airflow/dags/google_trends_dag.py", line 41, in __init__
    self.dag:DAG = self.create_dag()
  File "/opt/airflow/dags/google_trends_dag.py", line 54, in create_dag
    update_monthly: PythonOperator = PythonOperator(
  File "/home/airflow/.local/lib/python3.9/site-packages/airflow/models/baseoperator.py", line 429, in apply_defaults
    result = func(self, **kwargs, default_args=default_args)
  File "/home/airflow/.local/lib/python3.9/site-packages/airflow/operators/python.py", line 168, in __init__
    raise AirflowException("`python_callable` param must be callable")
airflow.exceptions.AirflowException: `python_callable` param must be callable
[2023-07-29T22:51:48.667+0300] {processor.py:811} WARNING - No viable dags retrieved from /opt/airflow/dags/google_trends_dag.py
[2023-07-29T22:51:48.692+0300] {processor.py:178} INFO - Processing /opt/airflow/dags/google_trends_dag.py took 0.054 seconds
[2023-07-29T22:52:18.845+0300] {processor.py:156} INFO - Started process (PID=190) to work on /opt/airflow/dags/google_trends_dag.py
[2023-07-29T22:52:18.847+0300] {processor.py:799} INFO - Processing file /opt/airflow/dags/google_trends_dag.py for tasks to queue
[2023-07-29T22:52:18.848+0300] {logging_mixin.py:149} INFO - [2023-07-29T22:52:18.847+0300] {dagbag.py:541} INFO - Filling up the DagBag from /opt/airflow/dags/google_trends_dag.py
[2023-07-29T22:52:18.868+0300] {logging_mixin.py:149} INFO - [2023-07-29T22:52:18.866+0300] {dagbag.py:350} ERROR - Failed to import: /opt/airflow/dags/google_trends_dag.py
Traceback (most recent call last):
  File "/home/airflow/.local/lib/python3.9/site-packages/airflow/models/dagbag.py", line 346, in parse
    loader.exec_module(new_module)
  File "<frozen importlib._bootstrap_external>", line 850, in exec_module
  File "<frozen importlib._bootstrap>", line 228, in _call_with_frames_removed
  File "/opt/airflow/dags/google_trends_dag.py", line 74, in <module>
    dag_creator = GooogleTrendsMonthly()
  File "/opt/airflow/dags/google_trends_dag.py", line 41, in __init__
    self.dag:DAG = self.create_dag()
  File "/opt/airflow/dags/google_trends_dag.py", line 54, in create_dag
    update_monthly: PythonOperator = PythonOperator(
  File "/home/airflow/.local/lib/python3.9/site-packages/airflow/models/baseoperator.py", line 429, in apply_defaults
    result = func(self, **kwargs, default_args=default_args)
  File "/home/airflow/.local/lib/python3.9/site-packages/airflow/operators/python.py", line 168, in __init__
    raise AirflowException("`python_callable` param must be callable")
airflow.exceptions.AirflowException: `python_callable` param must be callable
[2023-07-29T22:52:18.869+0300] {processor.py:811} WARNING - No viable dags retrieved from /opt/airflow/dags/google_trends_dag.py
[2023-07-29T22:52:18.898+0300] {processor.py:178} INFO - Processing /opt/airflow/dags/google_trends_dag.py took 0.057 seconds
[2023-07-29T22:52:49.008+0300] {processor.py:156} INFO - Started process (PID=198) to work on /opt/airflow/dags/google_trends_dag.py
[2023-07-29T22:52:49.009+0300] {processor.py:799} INFO - Processing file /opt/airflow/dags/google_trends_dag.py for tasks to queue
[2023-07-29T22:52:49.009+0300] {logging_mixin.py:149} INFO - [2023-07-29T22:52:49.009+0300] {dagbag.py:541} INFO - Filling up the DagBag from /opt/airflow/dags/google_trends_dag.py
[2023-07-29T22:52:49.024+0300] {logging_mixin.py:149} INFO - [2023-07-29T22:52:49.022+0300] {dagbag.py:350} ERROR - Failed to import: /opt/airflow/dags/google_trends_dag.py
Traceback (most recent call last):
  File "/home/airflow/.local/lib/python3.9/site-packages/airflow/models/dagbag.py", line 346, in parse
    loader.exec_module(new_module)
  File "<frozen importlib._bootstrap_external>", line 850, in exec_module
  File "<frozen importlib._bootstrap>", line 228, in _call_with_frames_removed
  File "/opt/airflow/dags/google_trends_dag.py", line 74, in <module>
    dag_creator = GooogleTrendsMonthly()
  File "/opt/airflow/dags/google_trends_dag.py", line 41, in __init__
    self.dag:DAG = self.create_dag()
  File "/opt/airflow/dags/google_trends_dag.py", line 54, in create_dag
    update_monthly: PythonOperator = PythonOperator(
  File "/home/airflow/.local/lib/python3.9/site-packages/airflow/models/baseoperator.py", line 429, in apply_defaults
    result = func(self, **kwargs, default_args=default_args)
  File "/home/airflow/.local/lib/python3.9/site-packages/airflow/operators/python.py", line 168, in __init__
    raise AirflowException("`python_callable` param must be callable")
airflow.exceptions.AirflowException: `python_callable` param must be callable
[2023-07-29T22:52:49.024+0300] {processor.py:811} WARNING - No viable dags retrieved from /opt/airflow/dags/google_trends_dag.py
[2023-07-29T22:52:49.050+0300] {processor.py:178} INFO - Processing /opt/airflow/dags/google_trends_dag.py took 0.046 seconds
[2023-07-29T22:53:19.204+0300] {processor.py:156} INFO - Started process (PID=206) to work on /opt/airflow/dags/google_trends_dag.py
[2023-07-29T22:53:19.205+0300] {processor.py:799} INFO - Processing file /opt/airflow/dags/google_trends_dag.py for tasks to queue
[2023-07-29T22:53:19.206+0300] {logging_mixin.py:149} INFO - [2023-07-29T22:53:19.206+0300] {dagbag.py:541} INFO - Filling up the DagBag from /opt/airflow/dags/google_trends_dag.py
[2023-07-29T22:53:19.223+0300] {logging_mixin.py:149} INFO - [2023-07-29T22:53:19.221+0300] {dagbag.py:350} ERROR - Failed to import: /opt/airflow/dags/google_trends_dag.py
Traceback (most recent call last):
  File "/home/airflow/.local/lib/python3.9/site-packages/airflow/models/dagbag.py", line 346, in parse
    loader.exec_module(new_module)
  File "<frozen importlib._bootstrap_external>", line 850, in exec_module
  File "<frozen importlib._bootstrap>", line 228, in _call_with_frames_removed
  File "/opt/airflow/dags/google_trends_dag.py", line 74, in <module>
    dag_creator = GooogleTrendsMonthly()
  File "/opt/airflow/dags/google_trends_dag.py", line 41, in __init__
    self.dag:DAG = self.create_dag()
  File "/opt/airflow/dags/google_trends_dag.py", line 54, in create_dag
    update_monthly: PythonOperator = PythonOperator(
  File "/home/airflow/.local/lib/python3.9/site-packages/airflow/models/baseoperator.py", line 429, in apply_defaults
    result = func(self, **kwargs, default_args=default_args)
  File "/home/airflow/.local/lib/python3.9/site-packages/airflow/operators/python.py", line 168, in __init__
    raise AirflowException("`python_callable` param must be callable")
airflow.exceptions.AirflowException: `python_callable` param must be callable
[2023-07-29T22:53:19.224+0300] {processor.py:811} WARNING - No viable dags retrieved from /opt/airflow/dags/google_trends_dag.py
[2023-07-29T22:53:19.251+0300] {processor.py:178} INFO - Processing /opt/airflow/dags/google_trends_dag.py took 0.052 seconds
[2023-07-29T22:53:49.384+0300] {processor.py:156} INFO - Started process (PID=214) to work on /opt/airflow/dags/google_trends_dag.py
[2023-07-29T22:53:49.385+0300] {processor.py:799} INFO - Processing file /opt/airflow/dags/google_trends_dag.py for tasks to queue
[2023-07-29T22:53:49.386+0300] {logging_mixin.py:149} INFO - [2023-07-29T22:53:49.386+0300] {dagbag.py:541} INFO - Filling up the DagBag from /opt/airflow/dags/google_trends_dag.py
[2023-07-29T22:53:49.405+0300] {logging_mixin.py:149} INFO - [2023-07-29T22:53:49.403+0300] {dagbag.py:350} ERROR - Failed to import: /opt/airflow/dags/google_trends_dag.py
Traceback (most recent call last):
  File "/home/airflow/.local/lib/python3.9/site-packages/airflow/models/dagbag.py", line 346, in parse
    loader.exec_module(new_module)
  File "<frozen importlib._bootstrap_external>", line 850, in exec_module
  File "<frozen importlib._bootstrap>", line 228, in _call_with_frames_removed
  File "/opt/airflow/dags/google_trends_dag.py", line 74, in <module>
    dag_creator = GooogleTrendsMonthly()
  File "/opt/airflow/dags/google_trends_dag.py", line 41, in __init__
    self.dag:DAG = self.create_dag()
  File "/opt/airflow/dags/google_trends_dag.py", line 54, in create_dag
    update_monthly: PythonOperator = PythonOperator(
  File "/home/airflow/.local/lib/python3.9/site-packages/airflow/models/baseoperator.py", line 429, in apply_defaults
    result = func(self, **kwargs, default_args=default_args)
  File "/home/airflow/.local/lib/python3.9/site-packages/airflow/operators/python.py", line 168, in __init__
    raise AirflowException("`python_callable` param must be callable")
airflow.exceptions.AirflowException: `python_callable` param must be callable
[2023-07-29T22:53:49.406+0300] {processor.py:811} WARNING - No viable dags retrieved from /opt/airflow/dags/google_trends_dag.py
[2023-07-29T22:53:49.437+0300] {processor.py:178} INFO - Processing /opt/airflow/dags/google_trends_dag.py took 0.057 seconds
[2023-07-29T22:54:19.587+0300] {processor.py:156} INFO - Started process (PID=222) to work on /opt/airflow/dags/google_trends_dag.py
[2023-07-29T22:54:19.588+0300] {processor.py:799} INFO - Processing file /opt/airflow/dags/google_trends_dag.py for tasks to queue
[2023-07-29T22:54:19.589+0300] {logging_mixin.py:149} INFO - [2023-07-29T22:54:19.589+0300] {dagbag.py:541} INFO - Filling up the DagBag from /opt/airflow/dags/google_trends_dag.py
[2023-07-29T22:54:19.610+0300] {logging_mixin.py:149} INFO - [2023-07-29T22:54:19.607+0300] {dagbag.py:350} ERROR - Failed to import: /opt/airflow/dags/google_trends_dag.py
Traceback (most recent call last):
  File "/home/airflow/.local/lib/python3.9/site-packages/airflow/models/dagbag.py", line 346, in parse
    loader.exec_module(new_module)
  File "<frozen importlib._bootstrap_external>", line 850, in exec_module
  File "<frozen importlib._bootstrap>", line 228, in _call_with_frames_removed
  File "/opt/airflow/dags/google_trends_dag.py", line 74, in <module>
    dag_creator = GooogleTrendsMonthly()
  File "/opt/airflow/dags/google_trends_dag.py", line 41, in __init__
    self.dag:DAG = self.create_dag()
  File "/opt/airflow/dags/google_trends_dag.py", line 54, in create_dag
    update_monthly: PythonOperator = PythonOperator(
  File "/home/airflow/.local/lib/python3.9/site-packages/airflow/models/baseoperator.py", line 429, in apply_defaults
    result = func(self, **kwargs, default_args=default_args)
  File "/home/airflow/.local/lib/python3.9/site-packages/airflow/operators/python.py", line 168, in __init__
    raise AirflowException("`python_callable` param must be callable")
airflow.exceptions.AirflowException: `python_callable` param must be callable
[2023-07-29T22:54:19.610+0300] {processor.py:811} WARNING - No viable dags retrieved from /opt/airflow/dags/google_trends_dag.py
[2023-07-29T22:54:19.645+0300] {processor.py:178} INFO - Processing /opt/airflow/dags/google_trends_dag.py took 0.063 seconds
[2023-07-29T22:54:49.769+0300] {processor.py:156} INFO - Started process (PID=230) to work on /opt/airflow/dags/google_trends_dag.py
[2023-07-29T22:54:49.770+0300] {processor.py:799} INFO - Processing file /opt/airflow/dags/google_trends_dag.py for tasks to queue
[2023-07-29T22:54:49.771+0300] {logging_mixin.py:149} INFO - [2023-07-29T22:54:49.771+0300] {dagbag.py:541} INFO - Filling up the DagBag from /opt/airflow/dags/google_trends_dag.py
[2023-07-29T22:54:49.790+0300] {logging_mixin.py:149} INFO - [2023-07-29T22:54:49.788+0300] {dagbag.py:350} ERROR - Failed to import: /opt/airflow/dags/google_trends_dag.py
Traceback (most recent call last):
  File "/home/airflow/.local/lib/python3.9/site-packages/airflow/models/dagbag.py", line 346, in parse
    loader.exec_module(new_module)
  File "<frozen importlib._bootstrap_external>", line 850, in exec_module
  File "<frozen importlib._bootstrap>", line 228, in _call_with_frames_removed
  File "/opt/airflow/dags/google_trends_dag.py", line 74, in <module>
    dag_creator = GooogleTrendsMonthly()
  File "/opt/airflow/dags/google_trends_dag.py", line 41, in __init__
    self.dag:DAG = self.create_dag()
  File "/opt/airflow/dags/google_trends_dag.py", line 54, in create_dag
    update_monthly: PythonOperator = PythonOperator(
  File "/home/airflow/.local/lib/python3.9/site-packages/airflow/models/baseoperator.py", line 429, in apply_defaults
    result = func(self, **kwargs, default_args=default_args)
  File "/home/airflow/.local/lib/python3.9/site-packages/airflow/operators/python.py", line 168, in __init__
    raise AirflowException("`python_callable` param must be callable")
airflow.exceptions.AirflowException: `python_callable` param must be callable
[2023-07-29T22:54:49.791+0300] {processor.py:811} WARNING - No viable dags retrieved from /opt/airflow/dags/google_trends_dag.py
[2023-07-29T22:54:49.816+0300] {processor.py:178} INFO - Processing /opt/airflow/dags/google_trends_dag.py took 0.052 seconds
[2023-07-29T22:55:19.962+0300] {processor.py:156} INFO - Started process (PID=238) to work on /opt/airflow/dags/google_trends_dag.py
[2023-07-29T22:55:19.963+0300] {processor.py:799} INFO - Processing file /opt/airflow/dags/google_trends_dag.py for tasks to queue
[2023-07-29T22:55:19.964+0300] {logging_mixin.py:149} INFO - [2023-07-29T22:55:19.964+0300] {dagbag.py:541} INFO - Filling up the DagBag from /opt/airflow/dags/google_trends_dag.py
[2023-07-29T22:55:19.983+0300] {logging_mixin.py:149} INFO - [2023-07-29T22:55:19.981+0300] {dagbag.py:350} ERROR - Failed to import: /opt/airflow/dags/google_trends_dag.py
Traceback (most recent call last):
  File "/home/airflow/.local/lib/python3.9/site-packages/airflow/models/dagbag.py", line 346, in parse
    loader.exec_module(new_module)
  File "<frozen importlib._bootstrap_external>", line 850, in exec_module
  File "<frozen importlib._bootstrap>", line 228, in _call_with_frames_removed
  File "/opt/airflow/dags/google_trends_dag.py", line 74, in <module>
    dag_creator = GooogleTrendsMonthly()
  File "/opt/airflow/dags/google_trends_dag.py", line 41, in __init__
    self.dag:DAG = self.create_dag()
  File "/opt/airflow/dags/google_trends_dag.py", line 54, in create_dag
    update_monthly: PythonOperator = PythonOperator(
  File "/home/airflow/.local/lib/python3.9/site-packages/airflow/models/baseoperator.py", line 429, in apply_defaults
    result = func(self, **kwargs, default_args=default_args)
  File "/home/airflow/.local/lib/python3.9/site-packages/airflow/operators/python.py", line 168, in __init__
    raise AirflowException("`python_callable` param must be callable")
airflow.exceptions.AirflowException: `python_callable` param must be callable
[2023-07-29T22:55:19.983+0300] {processor.py:811} WARNING - No viable dags retrieved from /opt/airflow/dags/google_trends_dag.py
[2023-07-29T22:55:20.011+0300] {processor.py:178} INFO - Processing /opt/airflow/dags/google_trends_dag.py took 0.053 seconds
[2023-07-29T22:55:50.132+0300] {processor.py:156} INFO - Started process (PID=246) to work on /opt/airflow/dags/google_trends_dag.py
[2023-07-29T22:55:50.134+0300] {processor.py:799} INFO - Processing file /opt/airflow/dags/google_trends_dag.py for tasks to queue
[2023-07-29T22:55:50.135+0300] {logging_mixin.py:149} INFO - [2023-07-29T22:55:50.134+0300] {dagbag.py:541} INFO - Filling up the DagBag from /opt/airflow/dags/google_trends_dag.py
[2023-07-29T22:55:50.151+0300] {logging_mixin.py:149} INFO - [2023-07-29T22:55:50.149+0300] {dagbag.py:350} ERROR - Failed to import: /opt/airflow/dags/google_trends_dag.py
Traceback (most recent call last):
  File "/home/airflow/.local/lib/python3.9/site-packages/airflow/models/dagbag.py", line 346, in parse
    loader.exec_module(new_module)
  File "<frozen importlib._bootstrap_external>", line 850, in exec_module
  File "<frozen importlib._bootstrap>", line 228, in _call_with_frames_removed
  File "/opt/airflow/dags/google_trends_dag.py", line 74, in <module>
    dag_creator = GooogleTrendsMonthly()
  File "/opt/airflow/dags/google_trends_dag.py", line 41, in __init__
    self.dag:DAG = self.create_dag()
  File "/opt/airflow/dags/google_trends_dag.py", line 54, in create_dag
    update_monthly: PythonOperator = PythonOperator(
  File "/home/airflow/.local/lib/python3.9/site-packages/airflow/models/baseoperator.py", line 429, in apply_defaults
    result = func(self, **kwargs, default_args=default_args)
  File "/home/airflow/.local/lib/python3.9/site-packages/airflow/operators/python.py", line 168, in __init__
    raise AirflowException("`python_callable` param must be callable")
airflow.exceptions.AirflowException: `python_callable` param must be callable
[2023-07-29T22:55:50.152+0300] {processor.py:811} WARNING - No viable dags retrieved from /opt/airflow/dags/google_trends_dag.py
[2023-07-29T22:55:50.177+0300] {processor.py:178} INFO - Processing /opt/airflow/dags/google_trends_dag.py took 0.049 seconds
[2023-07-29T22:56:20.311+0300] {processor.py:156} INFO - Started process (PID=254) to work on /opt/airflow/dags/google_trends_dag.py
[2023-07-29T22:56:20.312+0300] {processor.py:799} INFO - Processing file /opt/airflow/dags/google_trends_dag.py for tasks to queue
[2023-07-29T22:56:20.313+0300] {logging_mixin.py:149} INFO - [2023-07-29T22:56:20.313+0300] {dagbag.py:541} INFO - Filling up the DagBag from /opt/airflow/dags/google_trends_dag.py
[2023-07-29T22:56:20.332+0300] {logging_mixin.py:149} INFO - [2023-07-29T22:56:20.330+0300] {dagbag.py:350} ERROR - Failed to import: /opt/airflow/dags/google_trends_dag.py
Traceback (most recent call last):
  File "/home/airflow/.local/lib/python3.9/site-packages/airflow/models/dagbag.py", line 346, in parse
    loader.exec_module(new_module)
  File "<frozen importlib._bootstrap_external>", line 850, in exec_module
  File "<frozen importlib._bootstrap>", line 228, in _call_with_frames_removed
  File "/opt/airflow/dags/google_trends_dag.py", line 74, in <module>
    dag_creator = GooogleTrendsMonthly()
  File "/opt/airflow/dags/google_trends_dag.py", line 41, in __init__
    self.dag:DAG = self.create_dag()
  File "/opt/airflow/dags/google_trends_dag.py", line 54, in create_dag
    update_monthly: PythonOperator = PythonOperator(
  File "/home/airflow/.local/lib/python3.9/site-packages/airflow/models/baseoperator.py", line 429, in apply_defaults
    result = func(self, **kwargs, default_args=default_args)
  File "/home/airflow/.local/lib/python3.9/site-packages/airflow/operators/python.py", line 168, in __init__
    raise AirflowException("`python_callable` param must be callable")
airflow.exceptions.AirflowException: `python_callable` param must be callable
[2023-07-29T22:56:20.333+0300] {processor.py:811} WARNING - No viable dags retrieved from /opt/airflow/dags/google_trends_dag.py
[2023-07-29T22:56:20.369+0300] {processor.py:178} INFO - Processing /opt/airflow/dags/google_trends_dag.py took 0.062 seconds
[2023-07-29T22:57:51.118+0300] {processor.py:156} INFO - Started process (PID=27) to work on /opt/airflow/dags/google_trends_dag.py
[2023-07-29T22:57:51.119+0300] {processor.py:799} INFO - Processing file /opt/airflow/dags/google_trends_dag.py for tasks to queue
[2023-07-29T22:57:51.120+0300] {logging_mixin.py:149} INFO - [2023-07-29T22:57:51.120+0300] {dagbag.py:541} INFO - Filling up the DagBag from /opt/airflow/dags/google_trends_dag.py
[2023-07-29T22:57:51.156+0300] {logging_mixin.py:149} INFO - [2023-07-29T22:57:51.155+0300] {dagbag.py:350} ERROR - Failed to import: /opt/airflow/dags/google_trends_dag.py
Traceback (most recent call last):
  File "/home/airflow/.local/lib/python3.9/site-packages/airflow/models/dagbag.py", line 346, in parse
    loader.exec_module(new_module)
  File "<frozen importlib._bootstrap_external>", line 850, in exec_module
  File "<frozen importlib._bootstrap>", line 228, in _call_with_frames_removed
  File "/opt/airflow/dags/google_trends_dag.py", line 74, in <module>
    dag_creator = GooogleTrendsMonthly()
  File "/opt/airflow/dags/google_trends_dag.py", line 41, in __init__
    self.dag:DAG = self.create_dag()
  File "/opt/airflow/dags/google_trends_dag.py", line 54, in create_dag
    update_monthly: PythonOperator = PythonOperator(
  File "/home/airflow/.local/lib/python3.9/site-packages/airflow/models/baseoperator.py", line 429, in apply_defaults
    result = func(self, **kwargs, default_args=default_args)
  File "/home/airflow/.local/lib/python3.9/site-packages/airflow/operators/python.py", line 168, in __init__
    raise AirflowException("`python_callable` param must be callable")
airflow.exceptions.AirflowException: `python_callable` param must be callable
[2023-07-29T22:57:51.157+0300] {processor.py:811} WARNING - No viable dags retrieved from /opt/airflow/dags/google_trends_dag.py
[2023-07-29T22:57:51.180+0300] {processor.py:178} INFO - Processing /opt/airflow/dags/google_trends_dag.py took 0.066 seconds
[2023-07-29T22:58:21.324+0300] {processor.py:156} INFO - Started process (PID=35) to work on /opt/airflow/dags/google_trends_dag.py
[2023-07-29T22:58:21.326+0300] {processor.py:799} INFO - Processing file /opt/airflow/dags/google_trends_dag.py for tasks to queue
[2023-07-29T22:58:21.327+0300] {logging_mixin.py:149} INFO - [2023-07-29T22:58:21.327+0300] {dagbag.py:541} INFO - Filling up the DagBag from /opt/airflow/dags/google_trends_dag.py
[2023-07-29T22:58:21.352+0300] {logging_mixin.py:149} INFO - [2023-07-29T22:58:21.350+0300] {dagbag.py:350} ERROR - Failed to import: /opt/airflow/dags/google_trends_dag.py
Traceback (most recent call last):
  File "/home/airflow/.local/lib/python3.9/site-packages/airflow/models/dagbag.py", line 346, in parse
    loader.exec_module(new_module)
  File "<frozen importlib._bootstrap_external>", line 850, in exec_module
  File "<frozen importlib._bootstrap>", line 228, in _call_with_frames_removed
  File "/opt/airflow/dags/google_trends_dag.py", line 74, in <module>
    dag_creator = GooogleTrendsMonthly()
  File "/opt/airflow/dags/google_trends_dag.py", line 41, in __init__
    self.dag:DAG = self.create_dag()
  File "/opt/airflow/dags/google_trends_dag.py", line 54, in create_dag
    update_monthly: PythonOperator = PythonOperator(
  File "/home/airflow/.local/lib/python3.9/site-packages/airflow/models/baseoperator.py", line 429, in apply_defaults
    result = func(self, **kwargs, default_args=default_args)
  File "/home/airflow/.local/lib/python3.9/site-packages/airflow/operators/python.py", line 168, in __init__
    raise AirflowException("`python_callable` param must be callable")
airflow.exceptions.AirflowException: `python_callable` param must be callable
[2023-07-29T22:58:21.352+0300] {processor.py:811} WARNING - No viable dags retrieved from /opt/airflow/dags/google_trends_dag.py
[2023-07-29T22:58:21.385+0300] {processor.py:178} INFO - Processing /opt/airflow/dags/google_trends_dag.py took 0.066 seconds
[2023-07-29T22:58:51.495+0300] {processor.py:156} INFO - Started process (PID=43) to work on /opt/airflow/dags/google_trends_dag.py
[2023-07-29T22:58:51.495+0300] {processor.py:799} INFO - Processing file /opt/airflow/dags/google_trends_dag.py for tasks to queue
[2023-07-29T22:58:51.496+0300] {logging_mixin.py:149} INFO - [2023-07-29T22:58:51.496+0300] {dagbag.py:541} INFO - Filling up the DagBag from /opt/airflow/dags/google_trends_dag.py
[2023-07-29T22:58:51.532+0300] {logging_mixin.py:149} INFO - [2023-07-29T22:58:51.529+0300] {dagbag.py:350} ERROR - Failed to import: /opt/airflow/dags/google_trends_dag.py
Traceback (most recent call last):
  File "/home/airflow/.local/lib/python3.9/site-packages/airflow/models/dagbag.py", line 346, in parse
    loader.exec_module(new_module)
  File "<frozen importlib._bootstrap_external>", line 850, in exec_module
  File "<frozen importlib._bootstrap>", line 228, in _call_with_frames_removed
  File "/opt/airflow/dags/google_trends_dag.py", line 74, in <module>
    dag_creator = GooogleTrendsMonthly()
  File "/opt/airflow/dags/google_trends_dag.py", line 41, in __init__
    self.dag:DAG = self.create_dag()
  File "/opt/airflow/dags/google_trends_dag.py", line 54, in create_dag
    update_monthly: PythonOperator = PythonOperator(
  File "/home/airflow/.local/lib/python3.9/site-packages/airflow/models/baseoperator.py", line 429, in apply_defaults
    result = func(self, **kwargs, default_args=default_args)
  File "/home/airflow/.local/lib/python3.9/site-packages/airflow/operators/python.py", line 168, in __init__
    raise AirflowException("`python_callable` param must be callable")
airflow.exceptions.AirflowException: `python_callable` param must be callable
[2023-07-29T22:58:51.533+0300] {processor.py:811} WARNING - No viable dags retrieved from /opt/airflow/dags/google_trends_dag.py
[2023-07-29T22:58:51.560+0300] {processor.py:178} INFO - Processing /opt/airflow/dags/google_trends_dag.py took 0.070 seconds
[2023-07-29T22:59:21.691+0300] {processor.py:156} INFO - Started process (PID=51) to work on /opt/airflow/dags/google_trends_dag.py
[2023-07-29T22:59:21.693+0300] {processor.py:799} INFO - Processing file /opt/airflow/dags/google_trends_dag.py for tasks to queue
[2023-07-29T22:59:21.694+0300] {logging_mixin.py:149} INFO - [2023-07-29T22:59:21.694+0300] {dagbag.py:541} INFO - Filling up the DagBag from /opt/airflow/dags/google_trends_dag.py
[2023-07-29T22:59:21.713+0300] {logging_mixin.py:149} INFO - [2023-07-29T22:59:21.711+0300] {dagbag.py:350} ERROR - Failed to import: /opt/airflow/dags/google_trends_dag.py
Traceback (most recent call last):
  File "/home/airflow/.local/lib/python3.9/site-packages/airflow/models/dagbag.py", line 346, in parse
    loader.exec_module(new_module)
  File "<frozen importlib._bootstrap_external>", line 850, in exec_module
  File "<frozen importlib._bootstrap>", line 228, in _call_with_frames_removed
  File "/opt/airflow/dags/google_trends_dag.py", line 74, in <module>
    dag_creator = GooogleTrendsMonthly()
  File "/opt/airflow/dags/google_trends_dag.py", line 41, in __init__
    self.dag:DAG = self.create_dag()
  File "/opt/airflow/dags/google_trends_dag.py", line 54, in create_dag
    update_monthly: PythonOperator = PythonOperator(
  File "/home/airflow/.local/lib/python3.9/site-packages/airflow/models/baseoperator.py", line 429, in apply_defaults
    result = func(self, **kwargs, default_args=default_args)
  File "/home/airflow/.local/lib/python3.9/site-packages/airflow/operators/python.py", line 168, in __init__
    raise AirflowException("`python_callable` param must be callable")
airflow.exceptions.AirflowException: `python_callable` param must be callable
[2023-07-29T22:59:21.713+0300] {processor.py:811} WARNING - No viable dags retrieved from /opt/airflow/dags/google_trends_dag.py
[2023-07-29T22:59:21.741+0300] {processor.py:178} INFO - Processing /opt/airflow/dags/google_trends_dag.py took 0.054 seconds
[2023-07-29T22:59:51.859+0300] {processor.py:156} INFO - Started process (PID=59) to work on /opt/airflow/dags/google_trends_dag.py
[2023-07-29T22:59:51.860+0300] {processor.py:799} INFO - Processing file /opt/airflow/dags/google_trends_dag.py for tasks to queue
[2023-07-29T22:59:51.861+0300] {logging_mixin.py:149} INFO - [2023-07-29T22:59:51.861+0300] {dagbag.py:541} INFO - Filling up the DagBag from /opt/airflow/dags/google_trends_dag.py
[2023-07-29T22:59:51.884+0300] {logging_mixin.py:149} INFO - [2023-07-29T22:59:51.882+0300] {dagbag.py:350} ERROR - Failed to import: /opt/airflow/dags/google_trends_dag.py
Traceback (most recent call last):
  File "/home/airflow/.local/lib/python3.9/site-packages/airflow/models/dagbag.py", line 346, in parse
    loader.exec_module(new_module)
  File "<frozen importlib._bootstrap_external>", line 850, in exec_module
  File "<frozen importlib._bootstrap>", line 228, in _call_with_frames_removed
  File "/opt/airflow/dags/google_trends_dag.py", line 74, in <module>
    dag_creator = GooogleTrendsMonthly()
  File "/opt/airflow/dags/google_trends_dag.py", line 41, in __init__
    self.dag:DAG = self.create_dag()
  File "/opt/airflow/dags/google_trends_dag.py", line 54, in create_dag
    update_monthly: PythonOperator = PythonOperator(
  File "/home/airflow/.local/lib/python3.9/site-packages/airflow/models/baseoperator.py", line 429, in apply_defaults
    result = func(self, **kwargs, default_args=default_args)
  File "/home/airflow/.local/lib/python3.9/site-packages/airflow/operators/python.py", line 168, in __init__
    raise AirflowException("`python_callable` param must be callable")
airflow.exceptions.AirflowException: `python_callable` param must be callable
[2023-07-29T22:59:51.885+0300] {processor.py:811} WARNING - No viable dags retrieved from /opt/airflow/dags/google_trends_dag.py
[2023-07-29T22:59:51.911+0300] {processor.py:178} INFO - Processing /opt/airflow/dags/google_trends_dag.py took 0.055 seconds
[2023-07-29T23:00:22.055+0300] {processor.py:156} INFO - Started process (PID=67) to work on /opt/airflow/dags/google_trends_dag.py
[2023-07-29T23:00:22.057+0300] {processor.py:799} INFO - Processing file /opt/airflow/dags/google_trends_dag.py for tasks to queue
[2023-07-29T23:00:22.059+0300] {logging_mixin.py:149} INFO - [2023-07-29T23:00:22.059+0300] {dagbag.py:541} INFO - Filling up the DagBag from /opt/airflow/dags/google_trends_dag.py
[2023-07-29T23:00:22.082+0300] {logging_mixin.py:149} INFO - [2023-07-29T23:00:22.080+0300] {dagbag.py:350} ERROR - Failed to import: /opt/airflow/dags/google_trends_dag.py
Traceback (most recent call last):
  File "/home/airflow/.local/lib/python3.9/site-packages/airflow/models/dagbag.py", line 346, in parse
    loader.exec_module(new_module)
  File "<frozen importlib._bootstrap_external>", line 850, in exec_module
  File "<frozen importlib._bootstrap>", line 228, in _call_with_frames_removed
  File "/opt/airflow/dags/google_trends_dag.py", line 74, in <module>
    dag_creator = GooogleTrendsMonthly()
  File "/opt/airflow/dags/google_trends_dag.py", line 41, in __init__
    self.dag:DAG = self.create_dag()
  File "/opt/airflow/dags/google_trends_dag.py", line 54, in create_dag
    update_monthly: PythonOperator = PythonOperator(
  File "/home/airflow/.local/lib/python3.9/site-packages/airflow/models/baseoperator.py", line 429, in apply_defaults
    result = func(self, **kwargs, default_args=default_args)
  File "/home/airflow/.local/lib/python3.9/site-packages/airflow/operators/python.py", line 168, in __init__
    raise AirflowException("`python_callable` param must be callable")
airflow.exceptions.AirflowException: `python_callable` param must be callable
[2023-07-29T23:00:22.084+0300] {processor.py:811} WARNING - No viable dags retrieved from /opt/airflow/dags/google_trends_dag.py
[2023-07-29T23:00:22.121+0300] {processor.py:178} INFO - Processing /opt/airflow/dags/google_trends_dag.py took 0.070 seconds
[2023-07-29T23:00:52.285+0300] {processor.py:156} INFO - Started process (PID=75) to work on /opt/airflow/dags/google_trends_dag.py
[2023-07-29T23:00:52.286+0300] {processor.py:799} INFO - Processing file /opt/airflow/dags/google_trends_dag.py for tasks to queue
[2023-07-29T23:00:52.287+0300] {logging_mixin.py:149} INFO - [2023-07-29T23:00:52.287+0300] {dagbag.py:541} INFO - Filling up the DagBag from /opt/airflow/dags/google_trends_dag.py
[2023-07-29T23:00:52.305+0300] {logging_mixin.py:149} INFO - [2023-07-29T23:00:52.303+0300] {dagbag.py:350} ERROR - Failed to import: /opt/airflow/dags/google_trends_dag.py
Traceback (most recent call last):
  File "/home/airflow/.local/lib/python3.9/site-packages/airflow/models/dagbag.py", line 346, in parse
    loader.exec_module(new_module)
  File "<frozen importlib._bootstrap_external>", line 850, in exec_module
  File "<frozen importlib._bootstrap>", line 228, in _call_with_frames_removed
  File "/opt/airflow/dags/google_trends_dag.py", line 74, in <module>
    dag_creator = GooogleTrendsMonthly()
  File "/opt/airflow/dags/google_trends_dag.py", line 41, in __init__
    self.dag:DAG = self.create_dag()
  File "/opt/airflow/dags/google_trends_dag.py", line 54, in create_dag
    update_monthly: PythonOperator = PythonOperator(
  File "/home/airflow/.local/lib/python3.9/site-packages/airflow/models/baseoperator.py", line 429, in apply_defaults
    result = func(self, **kwargs, default_args=default_args)
  File "/home/airflow/.local/lib/python3.9/site-packages/airflow/operators/python.py", line 168, in __init__
    raise AirflowException("`python_callable` param must be callable")
airflow.exceptions.AirflowException: `python_callable` param must be callable
[2023-07-29T23:00:52.305+0300] {processor.py:811} WARNING - No viable dags retrieved from /opt/airflow/dags/google_trends_dag.py
[2023-07-29T23:00:52.331+0300] {processor.py:178} INFO - Processing /opt/airflow/dags/google_trends_dag.py took 0.051 seconds
[2023-07-29T23:01:22.444+0300] {processor.py:156} INFO - Started process (PID=83) to work on /opt/airflow/dags/google_trends_dag.py
[2023-07-29T23:01:22.445+0300] {processor.py:799} INFO - Processing file /opt/airflow/dags/google_trends_dag.py for tasks to queue
[2023-07-29T23:01:22.446+0300] {logging_mixin.py:149} INFO - [2023-07-29T23:01:22.446+0300] {dagbag.py:541} INFO - Filling up the DagBag from /opt/airflow/dags/google_trends_dag.py
[2023-07-29T23:01:22.460+0300] {logging_mixin.py:149} INFO - [2023-07-29T23:01:22.458+0300] {dagbag.py:350} ERROR - Failed to import: /opt/airflow/dags/google_trends_dag.py
Traceback (most recent call last):
  File "/home/airflow/.local/lib/python3.9/site-packages/airflow/models/dagbag.py", line 346, in parse
    loader.exec_module(new_module)
  File "<frozen importlib._bootstrap_external>", line 850, in exec_module
  File "<frozen importlib._bootstrap>", line 228, in _call_with_frames_removed
  File "/opt/airflow/dags/google_trends_dag.py", line 74, in <module>
    dag_creator = GooogleTrendsMonthly()
  File "/opt/airflow/dags/google_trends_dag.py", line 41, in __init__
    self.dag:DAG = self.create_dag()
  File "/opt/airflow/dags/google_trends_dag.py", line 54, in create_dag
    update_monthly: PythonOperator = PythonOperator(
  File "/home/airflow/.local/lib/python3.9/site-packages/airflow/models/baseoperator.py", line 429, in apply_defaults
    result = func(self, **kwargs, default_args=default_args)
  File "/home/airflow/.local/lib/python3.9/site-packages/airflow/operators/python.py", line 168, in __init__
    raise AirflowException("`python_callable` param must be callable")
airflow.exceptions.AirflowException: `python_callable` param must be callable
[2023-07-29T23:01:22.460+0300] {processor.py:811} WARNING - No viable dags retrieved from /opt/airflow/dags/google_trends_dag.py
[2023-07-29T23:01:22.488+0300] {processor.py:178} INFO - Processing /opt/airflow/dags/google_trends_dag.py took 0.049 seconds
[2023-07-29T23:01:52.639+0300] {processor.py:156} INFO - Started process (PID=91) to work on /opt/airflow/dags/google_trends_dag.py
[2023-07-29T23:01:52.640+0300] {processor.py:799} INFO - Processing file /opt/airflow/dags/google_trends_dag.py for tasks to queue
[2023-07-29T23:01:52.640+0300] {logging_mixin.py:149} INFO - [2023-07-29T23:01:52.640+0300] {dagbag.py:541} INFO - Filling up the DagBag from /opt/airflow/dags/google_trends_dag.py
[2023-07-29T23:01:52.656+0300] {logging_mixin.py:149} INFO - [2023-07-29T23:01:52.654+0300] {dagbag.py:350} ERROR - Failed to import: /opt/airflow/dags/google_trends_dag.py
Traceback (most recent call last):
  File "/home/airflow/.local/lib/python3.9/site-packages/airflow/models/dagbag.py", line 346, in parse
    loader.exec_module(new_module)
  File "<frozen importlib._bootstrap_external>", line 850, in exec_module
  File "<frozen importlib._bootstrap>", line 228, in _call_with_frames_removed
  File "/opt/airflow/dags/google_trends_dag.py", line 74, in <module>
    dag_creator = GooogleTrendsMonthly()
  File "/opt/airflow/dags/google_trends_dag.py", line 41, in __init__
    self.dag:DAG = self.create_dag()
  File "/opt/airflow/dags/google_trends_dag.py", line 54, in create_dag
    update_monthly: PythonOperator = PythonOperator(
  File "/home/airflow/.local/lib/python3.9/site-packages/airflow/models/baseoperator.py", line 429, in apply_defaults
    result = func(self, **kwargs, default_args=default_args)
  File "/home/airflow/.local/lib/python3.9/site-packages/airflow/operators/python.py", line 168, in __init__
    raise AirflowException("`python_callable` param must be callable")
airflow.exceptions.AirflowException: `python_callable` param must be callable
[2023-07-29T23:01:52.656+0300] {processor.py:811} WARNING - No viable dags retrieved from /opt/airflow/dags/google_trends_dag.py
[2023-07-29T23:01:52.680+0300] {processor.py:178} INFO - Processing /opt/airflow/dags/google_trends_dag.py took 0.045 seconds
[2023-07-29T23:02:22.802+0300] {processor.py:156} INFO - Started process (PID=99) to work on /opt/airflow/dags/google_trends_dag.py
[2023-07-29T23:02:22.803+0300] {processor.py:799} INFO - Processing file /opt/airflow/dags/google_trends_dag.py for tasks to queue
[2023-07-29T23:02:22.803+0300] {logging_mixin.py:149} INFO - [2023-07-29T23:02:22.803+0300] {dagbag.py:541} INFO - Filling up the DagBag from /opt/airflow/dags/google_trends_dag.py
[2023-07-29T23:02:22.817+0300] {logging_mixin.py:149} INFO - [2023-07-29T23:02:22.815+0300] {dagbag.py:350} ERROR - Failed to import: /opt/airflow/dags/google_trends_dag.py
Traceback (most recent call last):
  File "/home/airflow/.local/lib/python3.9/site-packages/airflow/models/dagbag.py", line 346, in parse
    loader.exec_module(new_module)
  File "<frozen importlib._bootstrap_external>", line 850, in exec_module
  File "<frozen importlib._bootstrap>", line 228, in _call_with_frames_removed
  File "/opt/airflow/dags/google_trends_dag.py", line 74, in <module>
    dag_creator = GooogleTrendsMonthly()
  File "/opt/airflow/dags/google_trends_dag.py", line 41, in __init__
    self.dag:DAG = self.create_dag()
  File "/opt/airflow/dags/google_trends_dag.py", line 54, in create_dag
    update_monthly: PythonOperator = PythonOperator(
  File "/home/airflow/.local/lib/python3.9/site-packages/airflow/models/baseoperator.py", line 429, in apply_defaults
    result = func(self, **kwargs, default_args=default_args)
  File "/home/airflow/.local/lib/python3.9/site-packages/airflow/operators/python.py", line 168, in __init__
    raise AirflowException("`python_callable` param must be callable")
airflow.exceptions.AirflowException: `python_callable` param must be callable
[2023-07-29T23:02:22.817+0300] {processor.py:811} WARNING - No viable dags retrieved from /opt/airflow/dags/google_trends_dag.py
[2023-07-29T23:02:22.836+0300] {processor.py:178} INFO - Processing /opt/airflow/dags/google_trends_dag.py took 0.038 seconds
[2023-07-29T23:02:52.987+0300] {processor.py:156} INFO - Started process (PID=107) to work on /opt/airflow/dags/google_trends_dag.py
[2023-07-29T23:02:52.989+0300] {processor.py:799} INFO - Processing file /opt/airflow/dags/google_trends_dag.py for tasks to queue
[2023-07-29T23:02:52.990+0300] {logging_mixin.py:149} INFO - [2023-07-29T23:02:52.990+0300] {dagbag.py:541} INFO - Filling up the DagBag from /opt/airflow/dags/google_trends_dag.py
[2023-07-29T23:02:53.012+0300] {logging_mixin.py:149} INFO - [2023-07-29T23:02:53.010+0300] {dagbag.py:350} ERROR - Failed to import: /opt/airflow/dags/google_trends_dag.py
Traceback (most recent call last):
  File "/home/airflow/.local/lib/python3.9/site-packages/airflow/models/dagbag.py", line 346, in parse
    loader.exec_module(new_module)
  File "<frozen importlib._bootstrap_external>", line 850, in exec_module
  File "<frozen importlib._bootstrap>", line 228, in _call_with_frames_removed
  File "/opt/airflow/dags/google_trends_dag.py", line 74, in <module>
    dag_creator = GooogleTrendsMonthly()
  File "/opt/airflow/dags/google_trends_dag.py", line 41, in __init__
    self.dag:DAG = self.create_dag()
  File "/opt/airflow/dags/google_trends_dag.py", line 54, in create_dag
    update_monthly: PythonOperator = PythonOperator(
  File "/home/airflow/.local/lib/python3.9/site-packages/airflow/models/baseoperator.py", line 429, in apply_defaults
    result = func(self, **kwargs, default_args=default_args)
  File "/home/airflow/.local/lib/python3.9/site-packages/airflow/operators/python.py", line 168, in __init__
    raise AirflowException("`python_callable` param must be callable")
airflow.exceptions.AirflowException: `python_callable` param must be callable
[2023-07-29T23:02:53.013+0300] {processor.py:811} WARNING - No viable dags retrieved from /opt/airflow/dags/google_trends_dag.py
[2023-07-29T23:02:53.040+0300] {processor.py:178} INFO - Processing /opt/airflow/dags/google_trends_dag.py took 0.058 seconds
[2023-07-29T23:03:23.143+0300] {processor.py:156} INFO - Started process (PID=115) to work on /opt/airflow/dags/google_trends_dag.py
[2023-07-29T23:03:23.145+0300] {processor.py:799} INFO - Processing file /opt/airflow/dags/google_trends_dag.py for tasks to queue
[2023-07-29T23:03:23.146+0300] {logging_mixin.py:149} INFO - [2023-07-29T23:03:23.146+0300] {dagbag.py:541} INFO - Filling up the DagBag from /opt/airflow/dags/google_trends_dag.py
[2023-07-29T23:03:23.163+0300] {logging_mixin.py:149} INFO - [2023-07-29T23:03:23.161+0300] {dagbag.py:350} ERROR - Failed to import: /opt/airflow/dags/google_trends_dag.py
Traceback (most recent call last):
  File "/home/airflow/.local/lib/python3.9/site-packages/airflow/models/dagbag.py", line 346, in parse
    loader.exec_module(new_module)
  File "<frozen importlib._bootstrap_external>", line 850, in exec_module
  File "<frozen importlib._bootstrap>", line 228, in _call_with_frames_removed
  File "/opt/airflow/dags/google_trends_dag.py", line 74, in <module>
    dag_creator = GooogleTrendsMonthly()
  File "/opt/airflow/dags/google_trends_dag.py", line 41, in __init__
    self.dag:DAG = self.create_dag()
  File "/opt/airflow/dags/google_trends_dag.py", line 54, in create_dag
    update_monthly: PythonOperator = PythonOperator(
  File "/home/airflow/.local/lib/python3.9/site-packages/airflow/models/baseoperator.py", line 429, in apply_defaults
    result = func(self, **kwargs, default_args=default_args)
  File "/home/airflow/.local/lib/python3.9/site-packages/airflow/operators/python.py", line 168, in __init__
    raise AirflowException("`python_callable` param must be callable")
airflow.exceptions.AirflowException: `python_callable` param must be callable
[2023-07-29T23:03:23.164+0300] {processor.py:811} WARNING - No viable dags retrieved from /opt/airflow/dags/google_trends_dag.py
[2023-07-29T23:03:23.195+0300] {processor.py:178} INFO - Processing /opt/airflow/dags/google_trends_dag.py took 0.056 seconds
[2023-07-29T23:03:53.343+0300] {processor.py:156} INFO - Started process (PID=123) to work on /opt/airflow/dags/google_trends_dag.py
[2023-07-29T23:03:53.344+0300] {processor.py:799} INFO - Processing file /opt/airflow/dags/google_trends_dag.py for tasks to queue
[2023-07-29T23:03:53.345+0300] {logging_mixin.py:149} INFO - [2023-07-29T23:03:53.345+0300] {dagbag.py:541} INFO - Filling up the DagBag from /opt/airflow/dags/google_trends_dag.py
[2023-07-29T23:03:53.360+0300] {logging_mixin.py:149} INFO - [2023-07-29T23:03:53.358+0300] {dagbag.py:350} ERROR - Failed to import: /opt/airflow/dags/google_trends_dag.py
Traceback (most recent call last):
  File "/home/airflow/.local/lib/python3.9/site-packages/airflow/models/dagbag.py", line 346, in parse
    loader.exec_module(new_module)
  File "<frozen importlib._bootstrap_external>", line 850, in exec_module
  File "<frozen importlib._bootstrap>", line 228, in _call_with_frames_removed
  File "/opt/airflow/dags/google_trends_dag.py", line 74, in <module>
    dag_creator = GooogleTrendsMonthly()
  File "/opt/airflow/dags/google_trends_dag.py", line 41, in __init__
    self.dag:DAG = self.create_dag()
  File "/opt/airflow/dags/google_trends_dag.py", line 54, in create_dag
    update_monthly: PythonOperator = PythonOperator(
  File "/home/airflow/.local/lib/python3.9/site-packages/airflow/models/baseoperator.py", line 429, in apply_defaults
    result = func(self, **kwargs, default_args=default_args)
  File "/home/airflow/.local/lib/python3.9/site-packages/airflow/operators/python.py", line 168, in __init__
    raise AirflowException("`python_callable` param must be callable")
airflow.exceptions.AirflowException: `python_callable` param must be callable
[2023-07-29T23:03:53.360+0300] {processor.py:811} WARNING - No viable dags retrieved from /opt/airflow/dags/google_trends_dag.py
[2023-07-29T23:03:53.386+0300] {processor.py:178} INFO - Processing /opt/airflow/dags/google_trends_dag.py took 0.046 seconds
[2023-07-29T23:04:23.526+0300] {processor.py:156} INFO - Started process (PID=131) to work on /opt/airflow/dags/google_trends_dag.py
[2023-07-29T23:04:23.528+0300] {processor.py:799} INFO - Processing file /opt/airflow/dags/google_trends_dag.py for tasks to queue
[2023-07-29T23:04:23.529+0300] {logging_mixin.py:149} INFO - [2023-07-29T23:04:23.528+0300] {dagbag.py:541} INFO - Filling up the DagBag from /opt/airflow/dags/google_trends_dag.py
[2023-07-29T23:04:23.557+0300] {logging_mixin.py:149} INFO - [2023-07-29T23:04:23.554+0300] {dagbag.py:350} ERROR - Failed to import: /opt/airflow/dags/google_trends_dag.py
Traceback (most recent call last):
  File "/home/airflow/.local/lib/python3.9/site-packages/airflow/models/dagbag.py", line 346, in parse
    loader.exec_module(new_module)
  File "<frozen importlib._bootstrap_external>", line 850, in exec_module
  File "<frozen importlib._bootstrap>", line 228, in _call_with_frames_removed
  File "/opt/airflow/dags/google_trends_dag.py", line 74, in <module>
    dag_creator = GooogleTrendsMonthly()
  File "/opt/airflow/dags/google_trends_dag.py", line 41, in __init__
    self.dag:DAG = self.create_dag()
  File "/opt/airflow/dags/google_trends_dag.py", line 54, in create_dag
    update_monthly: PythonOperator = PythonOperator(
  File "/home/airflow/.local/lib/python3.9/site-packages/airflow/models/baseoperator.py", line 429, in apply_defaults
    result = func(self, **kwargs, default_args=default_args)
  File "/home/airflow/.local/lib/python3.9/site-packages/airflow/operators/python.py", line 168, in __init__
    raise AirflowException("`python_callable` param must be callable")
airflow.exceptions.AirflowException: `python_callable` param must be callable
[2023-07-29T23:04:23.558+0300] {processor.py:811} WARNING - No viable dags retrieved from /opt/airflow/dags/google_trends_dag.py
[2023-07-29T23:04:23.588+0300] {processor.py:178} INFO - Processing /opt/airflow/dags/google_trends_dag.py took 0.068 seconds
